Launching experiment meow_walker2d-v4-seed-1-alpha-0.2
Launching experiment meow_walker2d-v4-seed-1-alpha-0.3
/home/od2961/.conda/envs/similar-behavior/lib/python3.10/site-packages/pkg_resources/__init__.py:121: DeprecationWarning: pkg_resources is deprecated as an API
  warnings.warn("pkg_resources is deprecated as an API", DeprecationWarning)
/home/od2961/.conda/envs/similar-behavior/lib/python3.10/site-packages/pkg_resources/__init__.py:121: DeprecationWarning: pkg_resources is deprecated as an API
  warnings.warn("pkg_resources is deprecated as an API", DeprecationWarning)
/home/od2961/.conda/envs/similar-behavior/lib/python3.10/site-packages/pkg_resources/__init__.py:2870: DeprecationWarning: Deprecated call to `pkg_resources.declare_namespace('google')`.
Implementing implicit namespace packages (as specified in PEP 420) is preferred to `pkg_resources.declare_namespace`. See https://setuptools.pypa.io/en/latest/references/keywords.html#keyword-namespace-packages
  declare_namespace(pkg)
/home/od2961/.conda/envs/similar-behavior/lib/python3.10/site-packages/pkg_resources/__init__.py:2870: DeprecationWarning: Deprecated call to `pkg_resources.declare_namespace('google')`.
Implementing implicit namespace packages (as specified in PEP 420) is preferred to `pkg_resources.declare_namespace`. See https://setuptools.pypa.io/en/latest/references/keywords.html#keyword-namespace-packages
  declare_namespace(pkg)
/home/od2961/.conda/envs/similar-behavior/lib/python3.10/site-packages/pkg_resources/__init__.py:2870: DeprecationWarning: Deprecated call to `pkg_resources.declare_namespace('mpl_toolkits')`.
Implementing implicit namespace packages (as specified in PEP 420) is preferred to `pkg_resources.declare_namespace`. See https://setuptools.pypa.io/en/latest/references/keywords.html#keyword-namespace-packages
  declare_namespace(pkg)
/home/od2961/.conda/envs/similar-behavior/lib/python3.10/site-packages/pkg_resources/__init__.py:2870: DeprecationWarning: Deprecated call to `pkg_resources.declare_namespace('mpl_toolkits')`.
Implementing implicit namespace packages (as specified in PEP 420) is preferred to `pkg_resources.declare_namespace`. See https://setuptools.pypa.io/en/latest/references/keywords.html#keyword-namespace-packages
  declare_namespace(pkg)
/home/od2961/.conda/envs/similar-behavior/lib/python3.10/site-packages/pkg_resources/__init__.py:2870: DeprecationWarning: Deprecated call to `pkg_resources.declare_namespace('google')`.
Implementing implicit namespace packages (as specified in PEP 420) is preferred to `pkg_resources.declare_namespace`. See https://setuptools.pypa.io/en/latest/references/keywords.html#keyword-namespace-packages
  declare_namespace(pkg)
/home/od2961/.conda/envs/similar-behavior/lib/python3.10/site-packages/pkg_resources/__init__.py:2870: DeprecationWarning: Deprecated call to `pkg_resources.declare_namespace('google')`.
Implementing implicit namespace packages (as specified in PEP 420) is preferred to `pkg_resources.declare_namespace`. See https://setuptools.pypa.io/en/latest/references/keywords.html#keyword-namespace-packages
  declare_namespace(pkg)
wandb: Network error (ConnectionError), entering retry loop.
wandb: Network error (ConnectionError), entering retry loop.
wandb: W&B API key is configured. Use `wandb login --relogin` to force relogin
wandb: W&B API key is configured. Use `wandb login --relogin` to force relogin
wandb: - Waiting for wandb.init()...wandb: - Waiting for wandb.init()...wandb: \ Waiting for wandb.init()...wandb: \ Waiting for wandb.init()...wandb: | Waiting for wandb.init()...wandb: | Waiting for wandb.init()...wandb: Network error (ConnectionError), entering retry loop.
wandb: Network error (ConnectionError), entering retry loop.
wandb: / Waiting for wandb.init()...wandb: / Waiting for wandb.init()...wandb: - Waiting for wandb.init()...wandb: - Waiting for wandb.init()...wandb: \ Waiting for wandb.init()...wandb: \ Waiting for wandb.init()...wandb: | Waiting for wandb.init()...wandb: | Waiting for wandb.init()...wandb: / Waiting for wandb.init()...wandb: / Waiting for wandb.init()...wandb: - Waiting for wandb.init()...wandb: - Waiting for wandb.init()...wandb: \ Waiting for wandb.init()...wandb: \ Waiting for wandb.init()...wandb: | Waiting for wandb.init()...wandb: | Waiting for wandb.init()...wandb: / Waiting for wandb.init()...wandb: / Waiting for wandb.init()...wandb: - Waiting for wandb.init()...wandb: - Waiting for wandb.init()...wandb: \ Waiting for wandb.init()...wandb: \ Waiting for wandb.init()...wandb: | Waiting for wandb.init()...wandb: | Waiting for wandb.init()...wandb: / Waiting for wandb.init()...wandb: / Waiting for wandb.init()...wandb: - Waiting for wandb.init()...wandb: - Waiting for wandb.init()...wandb: \ Waiting for wandb.init()...wandb: \ Waiting for wandb.init()...wandb: | Waiting for wandb.init()...wandb: | Waiting for wandb.init()...wandb: / Waiting for wandb.init()...wandb: / Waiting for wandb.init()...wandb: - Waiting for wandb.init()...wandb: - Waiting for wandb.init()...wandb: \ Waiting for wandb.init()...wandb: \ Waiting for wandb.init()...wandb: | Waiting for wandb.init()...wandb: | Waiting for wandb.init()...wandb: / Waiting for wandb.init()...wandb: / Waiting for wandb.init()...wandb: - Waiting for wandb.init()...wandb: - Waiting for wandb.init()...wandb: \ Waiting for wandb.init()...wandb: \ Waiting for wandb.init()...wandb: | Waiting for wandb.init()...wandb: | Waiting for wandb.init()...wandb: / Waiting for wandb.init()...wandb: / Waiting for wandb.init()...wandb: - Waiting for wandb.init()...wandb: - Waiting for wandb.init()...wandb: \ Waiting for wandb.init()...wandb: \ Waiting for wandb.init()...wandb: | Waiting for wandb.init()...wandb: | Waiting for wandb.init()...wandb: / Waiting for wandb.init()...wandb: / Waiting for wandb.init()...wandb: - Waiting for wandb.init()...wandb: - Waiting for wandb.init()...wandb: \ Waiting for wandb.init()...wandb: \ Waiting for wandb.init()...wandb: | Waiting for wandb.init()...wandb: | Waiting for wandb.init()...wandb: / Waiting for wandb.init()...wandb: / Waiting for wandb.init()...wandb: - Waiting for wandb.init()...wandb: - Waiting for wandb.init()...wandb: \ Waiting for wandb.init()...wandb: \ Waiting for wandb.init()...wandb: | Waiting for wandb.init()...wandb: | Waiting for wandb.init()...wandb: / Waiting for wandb.init()...wandb: / Waiting for wandb.init()...wandb: - Waiting for wandb.init()...wandb: - Waiting for wandb.init()...wandb: \ Waiting for wandb.init()...wandb: \ Waiting for wandb.init()...wandb: | Waiting for wandb.init()...wandb: | Waiting for wandb.init()...wandb: / Waiting for wandb.init()...wandb: / Waiting for wandb.init()...wandb: - Waiting for wandb.init()...wandb: - Waiting for wandb.init()...wandb: \ Waiting for wandb.init()...wandb: \ Waiting for wandb.init()...wandb: | Waiting for wandb.init()...wandb: | Waiting for wandb.init()...wandb: / Waiting for wandb.init()...wandb: / Waiting for wandb.init()...wandb: - Waiting for wandb.init()...wandb: - Waiting for wandb.init()...wandb: \ Waiting for wandb.init()...wandb: \ Waiting for wandb.init()...wandb: | Waiting for wandb.init()...wandb: | Waiting for wandb.init()...wandb: / Waiting for wandb.init()...wandb: / Waiting for wandb.init()...wandb: - Waiting for wandb.init()...wandb: - Waiting for wandb.init()...wandb: \ Waiting for wandb.init()...wandb: \ Waiting for wandb.init()...wandb: | Waiting for wandb.init()...wandb: | Waiting for wandb.init()...wandb: / Waiting for wandb.init()...wandb: / Waiting for wandb.init()...wandb: - Waiting for wandb.init()...wandb: - Waiting for wandb.init()...wandb: \ Waiting for wandb.init()...wandb: \ Waiting for wandb.init()...wandb: | Waiting for wandb.init()...wandb: | Waiting for wandb.init()...WARNING:urllib3.connectionpool:Retrying (Retry(total=2, connect=None, read=None, redirect=None, status=None)) after connection broken by 'NewConnectionError('<urllib3.connection.HTTPSConnection object at 0x14ead9fbff10>: Failed to establish a new connection: [Errno -2] Name or service not known')': /api/5288891/envelope/
WARNING:urllib3.connectionpool:Retrying (Retry(total=1, connect=None, read=None, redirect=None, status=None)) after connection broken by 'NewConnectionError('<urllib3.connection.HTTPSConnection object at 0x14ead9fbceb0>: Failed to establish a new connection: [Errno -2] Name or service not known')': /api/5288891/envelope/
WARNING:urllib3.connectionpool:Retrying (Retry(total=0, connect=None, read=None, redirect=None, status=None)) after connection broken by 'NewConnectionError('<urllib3.connection.HTTPSConnection object at 0x14ead9fbcdc0>: Failed to establish a new connection: [Errno -2] Name or service not known')': /api/5288891/envelope/
WARNING:urllib3.connectionpool:Retrying (Retry(total=2, connect=None, read=None, redirect=None, status=None)) after connection broken by 'NewConnectionError('<urllib3.connection.HTTPSConnection object at 0x14a99f84be20>: Failed to establish a new connection: [Errno -2] Name or service not known')': /api/5288891/envelope/
WARNING:urllib3.connectionpool:Retrying (Retry(total=1, connect=None, read=None, redirect=None, status=None)) after connection broken by 'NewConnectionError('<urllib3.connection.HTTPSConnection object at 0x14a99f848ee0>: Failed to establish a new connection: [Errno -2] Name or service not known')': /api/5288891/envelope/
WARNING:urllib3.connectionpool:Retrying (Retry(total=0, connect=None, read=None, redirect=None, status=None)) after connection broken by 'NewConnectionError('<urllib3.connection.HTTPSConnection object at 0x14a99f848d30>: Failed to establish a new connection: [Errno -2] Name or service not known')': /api/5288891/envelope/
Problem at: /scratch/gpfs/od2961/similarity-paper/similar-behavior/cleanrl/cleanrl/meow_continuous_action.py 244 train
Traceback (most recent call last):
  File "/home/od2961/.conda/envs/similar-behavior/lib/python3.10/site-packages/wandb/sdk/wandb_init.py", line 1144, in init
    run = wi.init()
  File "/home/od2961/.conda/envs/similar-behavior/lib/python3.10/site-packages/wandb/sdk/wandb_init.py", line 773, in init
    raise error
wandb.errors.CommError: Error communicating with wandb process, exiting...
For more info see: https://docs.wandb.ai/guides/track/tracking-faq#initstarterror-error-communicating-with-wandb-process-
WARNING:urllib3.connectionpool:Retrying (Retry(total=2, connect=None, read=None, redirect=None, status=None)) after connection broken by 'NewConnectionError('<urllib3.connection.HTTPSConnection object at 0x14a99f84bf40>: Failed to establish a new connection: [Errno -2] Name or service not known')': /api/5288891/store/
WARNING:urllib3.connectionpool:Retrying (Retry(total=1, connect=None, read=None, redirect=None, status=None)) after connection broken by 'NewConnectionError('<urllib3.connection.HTTPSConnection object at 0x14a99f848e20>: Failed to establish a new connection: [Errno -2] Name or service not known')': /api/5288891/store/
WARNING:urllib3.connectionpool:Retrying (Retry(total=0, connect=None, read=None, redirect=None, status=None)) after connection broken by 'NewConnectionError('<urllib3.connection.HTTPSConnection object at 0x14a99f84bf70>: Failed to establish a new connection: [Errno -2] Name or service not known')': /api/5288891/store/
WARNING:urllib3.connectionpool:Retrying (Retry(total=2, connect=None, read=None, redirect=None, status=None)) after connection broken by 'NewConnectionError('<urllib3.connection.HTTPSConnection object at 0x14a99f8488e0>: Failed to establish a new connection: [Errno -2] Name or service not known')': /api/5288891/store/
WARNING:urllib3.connectionpool:Retrying (Retry(total=1, connect=None, read=None, redirect=None, status=None)) after connection broken by 'NewConnectionError('<urllib3.connection.HTTPSConnection object at 0x14a99f848700>: Failed to establish a new connection: [Errno -2] Name or service not known')': /api/5288891/store/
WARNING:urllib3.connectionpool:Retrying (Retry(total=0, connect=None, read=None, redirect=None, status=None)) after connection broken by 'NewConnectionError('<urllib3.connection.HTTPSConnection object at 0x14a99f848610>: Failed to establish a new connection: [Errno -2] Name or service not known')': /api/5288891/store/
Problem at: /scratch/gpfs/od2961/similarity-paper/similar-behavior/cleanrl/cleanrl/meow_continuous_action.py 244 train
Traceback (most recent call last):
  File "/home/od2961/.conda/envs/similar-behavior/lib/python3.10/site-packages/wandb/sdk/wandb_init.py", line 1144, in init
    run = wi.init()
  File "/home/od2961/.conda/envs/similar-behavior/lib/python3.10/site-packages/wandb/sdk/wandb_init.py", line 773, in init
    raise error
wandb.errors.CommError: Error communicating with wandb process, exiting...
For more info see: https://docs.wandb.ai/guides/track/tracking-faq#initstarterror-error-communicating-with-wandb-process-
WARNING:urllib3.connectionpool:Retrying (Retry(total=2, connect=None, read=None, redirect=None, status=None)) after connection broken by 'NewConnectionError('<urllib3.connection.HTTPSConnection object at 0x14ead9fbffd0>: Failed to establish a new connection: [Errno -2] Name or service not known')': /api/5288891/store/
WARNING:urllib3.connectionpool:Retrying (Retry(total=1, connect=None, read=None, redirect=None, status=None)) after connection broken by 'NewConnectionError('<urllib3.connection.HTTPSConnection object at 0x14ead9fbcdf0>: Failed to establish a new connection: [Errno -2] Name or service not known')': /api/5288891/store/
WARNING:urllib3.connectionpool:Retrying (Retry(total=0, connect=None, read=None, redirect=None, status=None)) after connection broken by 'NewConnectionError('<urllib3.connection.HTTPSConnection object at 0x14ead9fbff40>: Failed to establish a new connection: [Errno -2] Name or service not known')': /api/5288891/store/
WARNING:urllib3.connectionpool:Retrying (Retry(total=2, connect=None, read=None, redirect=None, status=None)) after connection broken by 'NewConnectionError('<urllib3.connection.HTTPSConnection object at 0x14ead9fbc8b0>: Failed to establish a new connection: [Errno -2] Name or service not known')': /api/5288891/store/
WARNING:urllib3.connectionpool:Retrying (Retry(total=1, connect=None, read=None, redirect=None, status=None)) after connection broken by 'NewConnectionError('<urllib3.connection.HTTPSConnection object at 0x14ead9fbc6d0>: Failed to establish a new connection: [Errno -2] Name or service not known')': /api/5288891/store/
WARNING:urllib3.connectionpool:Retrying (Retry(total=0, connect=None, read=None, redirect=None, status=None)) after connection broken by 'NewConnectionError('<urllib3.connection.HTTPSConnection object at 0x14ead9fbc520>: Failed to establish a new connection: [Errno -2] Name or service not known')': /api/5288891/store/
wandb: ERROR Abnormal program exit
Traceback (most recent call last):
  File "/home/od2961/.conda/envs/similar-behavior/lib/python3.10/site-packages/wandb/sdk/wandb_init.py", line 1144, in init
    run = wi.init()
  File "/home/od2961/.conda/envs/similar-behavior/lib/python3.10/site-packages/wandb/sdk/wandb_init.py", line 773, in init
    raise error
wandb.errors.CommError: Error communicating with wandb process, exiting...
For more info see: https://docs.wandb.ai/guides/track/tracking-faq#initstarterror-error-communicating-with-wandb-process-

The above exception was the direct cause of the following exception:

Traceback (most recent call last):
  File "/scratch/gpfs/od2961/similarity-paper/similar-behavior/cleanrl/cleanrl/meow_continuous_action.py", line 432, in <module>
    train()
  File "/scratch/gpfs/od2961/similarity-paper/similar-behavior/cleanrl/cleanrl/meow_continuous_action.py", line 244, in train
    wandb.init(
  File "/home/od2961/.conda/envs/similar-behavior/lib/python3.10/site-packages/wandb/sdk/wandb_init.py", line 1181, in init
    raise Exception("problem") from error_seen
Exception: problem
wandb: ERROR Abnormal program exit
Traceback (most recent call last):
  File "/home/od2961/.conda/envs/similar-behavior/lib/python3.10/site-packages/wandb/sdk/wandb_init.py", line 1144, in init
    run = wi.init()
  File "/home/od2961/.conda/envs/similar-behavior/lib/python3.10/site-packages/wandb/sdk/wandb_init.py", line 773, in init
    raise error
wandb.errors.CommError: Error communicating with wandb process, exiting...
For more info see: https://docs.wandb.ai/guides/track/tracking-faq#initstarterror-error-communicating-with-wandb-process-

The above exception was the direct cause of the following exception:

Traceback (most recent call last):
  File "/scratch/gpfs/od2961/similarity-paper/similar-behavior/cleanrl/cleanrl/meow_continuous_action.py", line 432, in <module>
    train()
  File "/scratch/gpfs/od2961/similarity-paper/similar-behavior/cleanrl/cleanrl/meow_continuous_action.py", line 244, in train
    wandb.init(
  File "/home/od2961/.conda/envs/similar-behavior/lib/python3.10/site-packages/wandb/sdk/wandb_init.py", line 1181, in init
    raise Exception("problem") from error_seen
Exception: problem
Launching experiment meow_walker2d-v4-seed-1-alpha-0.4
Launching experiment meow_walker2d-v4-seed-1-alpha-0.5
/home/od2961/.conda/envs/similar-behavior/lib/python3.10/site-packages/pkg_resources/__init__.py:121: DeprecationWarning: pkg_resources is deprecated as an API
  warnings.warn("pkg_resources is deprecated as an API", DeprecationWarning)
/home/od2961/.conda/envs/similar-behavior/lib/python3.10/site-packages/pkg_resources/__init__.py:121: DeprecationWarning: pkg_resources is deprecated as an API
  warnings.warn("pkg_resources is deprecated as an API", DeprecationWarning)
/home/od2961/.conda/envs/similar-behavior/lib/python3.10/site-packages/pkg_resources/__init__.py:2870: DeprecationWarning: Deprecated call to `pkg_resources.declare_namespace('google')`.
Implementing implicit namespace packages (as specified in PEP 420) is preferred to `pkg_resources.declare_namespace`. See https://setuptools.pypa.io/en/latest/references/keywords.html#keyword-namespace-packages
  declare_namespace(pkg)
/home/od2961/.conda/envs/similar-behavior/lib/python3.10/site-packages/pkg_resources/__init__.py:2870: DeprecationWarning: Deprecated call to `pkg_resources.declare_namespace('mpl_toolkits')`.
Implementing implicit namespace packages (as specified in PEP 420) is preferred to `pkg_resources.declare_namespace`. See https://setuptools.pypa.io/en/latest/references/keywords.html#keyword-namespace-packages
  declare_namespace(pkg)
/home/od2961/.conda/envs/similar-behavior/lib/python3.10/site-packages/pkg_resources/__init__.py:2870: DeprecationWarning: Deprecated call to `pkg_resources.declare_namespace('google')`.
Implementing implicit namespace packages (as specified in PEP 420) is preferred to `pkg_resources.declare_namespace`. See https://setuptools.pypa.io/en/latest/references/keywords.html#keyword-namespace-packages
  declare_namespace(pkg)
/home/od2961/.conda/envs/similar-behavior/lib/python3.10/site-packages/pkg_resources/__init__.py:2870: DeprecationWarning: Deprecated call to `pkg_resources.declare_namespace('google')`.
Implementing implicit namespace packages (as specified in PEP 420) is preferred to `pkg_resources.declare_namespace`. See https://setuptools.pypa.io/en/latest/references/keywords.html#keyword-namespace-packages
  declare_namespace(pkg)
/home/od2961/.conda/envs/similar-behavior/lib/python3.10/site-packages/pkg_resources/__init__.py:2870: DeprecationWarning: Deprecated call to `pkg_resources.declare_namespace('mpl_toolkits')`.
Implementing implicit namespace packages (as specified in PEP 420) is preferred to `pkg_resources.declare_namespace`. See https://setuptools.pypa.io/en/latest/references/keywords.html#keyword-namespace-packages
  declare_namespace(pkg)
/home/od2961/.conda/envs/similar-behavior/lib/python3.10/site-packages/pkg_resources/__init__.py:2870: DeprecationWarning: Deprecated call to `pkg_resources.declare_namespace('google')`.
Implementing implicit namespace packages (as specified in PEP 420) is preferred to `pkg_resources.declare_namespace`. See https://setuptools.pypa.io/en/latest/references/keywords.html#keyword-namespace-packages
  declare_namespace(pkg)
wandb: Network error (ConnectionError), entering retry loop.
wandb: Network error (ConnectionError), entering retry loop.
wandb: W&B API key is configured. Use `wandb login --relogin` to force relogin
wandb: W&B API key is configured. Use `wandb login --relogin` to force relogin
wandb: - Waiting for wandb.init()...wandb: - Waiting for wandb.init()...wandb: \ Waiting for wandb.init()...wandb: \ Waiting for wandb.init()...wandb: | Waiting for wandb.init()...wandb: | Waiting for wandb.init()...wandb: Network error (ConnectionError), entering retry loop.
wandb: Network error (ConnectionError), entering retry loop.
wandb: / Waiting for wandb.init()...wandb: / Waiting for wandb.init()...wandb: - Waiting for wandb.init()...wandb: - Waiting for wandb.init()...wandb: \ Waiting for wandb.init()...wandb: \ Waiting for wandb.init()...wandb: | Waiting for wandb.init()...wandb: | Waiting for wandb.init()...wandb: / Waiting for wandb.init()...wandb: / Waiting for wandb.init()...wandb: - Waiting for wandb.init()...wandb: - Waiting for wandb.init()...wandb: \ Waiting for wandb.init()...wandb: \ Waiting for wandb.init()...wandb: | Waiting for wandb.init()...wandb: | Waiting for wandb.init()...wandb: / Waiting for wandb.init()...wandb: / Waiting for wandb.init()...wandb: - Waiting for wandb.init()...wandb: - Waiting for wandb.init()...wandb: \ Waiting for wandb.init()...wandb: \ Waiting for wandb.init()...wandb: | Waiting for wandb.init()...wandb: | Waiting for wandb.init()...wandb: / Waiting for wandb.init()...wandb: / Waiting for wandb.init()...wandb: - Waiting for wandb.init()...wandb: - Waiting for wandb.init()...wandb: \ Waiting for wandb.init()...wandb: \ Waiting for wandb.init()...wandb: | Waiting for wandb.init()...wandb: | Waiting for wandb.init()...wandb: / Waiting for wandb.init()...wandb: / Waiting for wandb.init()...wandb: - Waiting for wandb.init()...wandb: - Waiting for wandb.init()...wandb: \ Waiting for wandb.init()...wandb: \ Waiting for wandb.init()...wandb: | Waiting for wandb.init()...wandb: | Waiting for wandb.init()...wandb: / Waiting for wandb.init()...wandb: / Waiting for wandb.init()...wandb: - Waiting for wandb.init()...wandb: - Waiting for wandb.init()...wandb: \ Waiting for wandb.init()...wandb: \ Waiting for wandb.init()...wandb: | Waiting for wandb.init()...wandb: | Waiting for wandb.init()...wandb: / Waiting for wandb.init()...wandb: / Waiting for wandb.init()...wandb: - Waiting for wandb.init()...wandb: - Waiting for wandb.init()...wandb: \ Waiting for wandb.init()...wandb: \ Waiting for wandb.init()...wandb: | Waiting for wandb.init()...wandb: | Waiting for wandb.init()...wandb: / Waiting for wandb.init()...wandb: / Waiting for wandb.init()...wandb: - Waiting for wandb.init()...wandb: - Waiting for wandb.init()...wandb: \ Waiting for wandb.init()...wandb: \ Waiting for wandb.init()...wandb: | Waiting for wandb.init()...wandb: | Waiting for wandb.init()...wandb: / Waiting for wandb.init()...wandb: / Waiting for wandb.init()...wandb: - Waiting for wandb.init()...wandb: - Waiting for wandb.init()...wandb: \ Waiting for wandb.init()...wandb: \ Waiting for wandb.init()...wandb: | Waiting for wandb.init()...wandb: | Waiting for wandb.init()...wandb: / Waiting for wandb.init()...wandb: / Waiting for wandb.init()...wandb: - Waiting for wandb.init()...wandb: - Waiting for wandb.init()...wandb: \ Waiting for wandb.init()...wandb: \ Waiting for wandb.init()...wandb: | Waiting for wandb.init()...wandb: | Waiting for wandb.init()...wandb: / Waiting for wandb.init()...wandb: / Waiting for wandb.init()...wandb: - Waiting for wandb.init()...wandb: - Waiting for wandb.init()...wandb: \ Waiting for wandb.init()...wandb: \ Waiting for wandb.init()...wandb: | Waiting for wandb.init()...wandb: | Waiting for wandb.init()...wandb: / Waiting for wandb.init()...wandb: / Waiting for wandb.init()...wandb: - Waiting for wandb.init()...wandb: - Waiting for wandb.init()...wandb: \ Waiting for wandb.init()...wandb: \ Waiting for wandb.init()...wandb: | Waiting for wandb.init()...wandb: | Waiting for wandb.init()...wandb: / Waiting for wandb.init()...wandb: / Waiting for wandb.init()...wandb: - Waiting for wandb.init()...wandb: - Waiting for wandb.init()...wandb: \ Waiting for wandb.init()...wandb: \ Waiting for wandb.init()...wandb: | Waiting for wandb.init()...wandb: | Waiting for wandb.init()...wandb: / Waiting for wandb.init()...wandb: / Waiting for wandb.init()...wandb: - Waiting for wandb.init()...wandb: - Waiting for wandb.init()...wandb: \ Waiting for wandb.init()...wandb: \ Waiting for wandb.init()...wandb: | Waiting for wandb.init()...wandb: | Waiting for wandb.init()...Problem at: /scratch/gpfs/od2961/similarity-paper/similar-behavior/cleanrl/cleanrl/meow_continuous_action.py 244 train
Traceback (most recent call last):
  File "/home/od2961/.conda/envs/similar-behavior/lib/python3.10/site-packages/wandb/sdk/wandb_init.py", line 1144, in init
    run = wi.init()
  File "/home/od2961/.conda/envs/similar-behavior/lib/python3.10/site-packages/wandb/sdk/wandb_init.py", line 773, in init
    raise error
wandb.errors.CommError: Error communicating with wandb process, exiting...
For more info see: https://docs.wandb.ai/guides/track/tracking-faq#initstarterror-error-communicating-with-wandb-process-
Problem at: /scratch/gpfs/od2961/similarity-paper/similar-behavior/cleanrl/cleanrl/meow_continuous_action.py 244 train
Traceback (most recent call last):
  File "/home/od2961/.conda/envs/similar-behavior/lib/python3.10/site-packages/wandb/sdk/wandb_init.py", line 1144, in init
    run = wi.init()
  File "/home/od2961/.conda/envs/similar-behavior/lib/python3.10/site-packages/wandb/sdk/wandb_init.py", line 773, in init
    raise error
wandb.errors.CommError: Error communicating with wandb process, exiting...
For more info see: https://docs.wandb.ai/guides/track/tracking-faq#initstarterror-error-communicating-with-wandb-process-
WARNING:urllib3.connectionpool:Retrying (Retry(total=2, connect=None, read=None, redirect=None, status=None)) after connection broken by 'NewConnectionError('<urllib3.connection.HTTPSConnection object at 0x153b04114d00>: Failed to establish a new connection: [Errno -2] Name or service not known')': /api/5288891/envelope/
WARNING:urllib3.connectionpool:Retrying (Retry(total=1, connect=None, read=None, redirect=None, status=None)) after connection broken by 'NewConnectionError('<urllib3.connection.HTTPSConnection object at 0x153b04114970>: Failed to establish a new connection: [Errno -2] Name or service not known')': /api/5288891/envelope/
WARNING:urllib3.connectionpool:Retrying (Retry(total=0, connect=None, read=None, redirect=None, status=None)) after connection broken by 'NewConnectionError('<urllib3.connection.HTTPSConnection object at 0x153b041150f0>: Failed to establish a new connection: [Errno -2] Name or service not known')': /api/5288891/envelope/
WARNING:urllib3.connectionpool:Retrying (Retry(total=2, connect=None, read=None, redirect=None, status=None)) after connection broken by 'NewConnectionError('<urllib3.connection.HTTPSConnection object at 0x153b041148b0>: Failed to establish a new connection: [Errno -2] Name or service not known')': /api/5288891/store/
WARNING:urllib3.connectionpool:Retrying (Retry(total=1, connect=None, read=None, redirect=None, status=None)) after connection broken by 'NewConnectionError('<urllib3.connection.HTTPSConnection object at 0x153b04114700>: Failed to establish a new connection: [Errno -2] Name or service not known')': /api/5288891/store/
WARNING:urllib3.connectionpool:Retrying (Retry(total=0, connect=None, read=None, redirect=None, status=None)) after connection broken by 'NewConnectionError('<urllib3.connection.HTTPSConnection object at 0x153b04114550>: Failed to establish a new connection: [Errno -2] Name or service not known')': /api/5288891/store/
WARNING:urllib3.connectionpool:Retrying (Retry(total=2, connect=None, read=None, redirect=None, status=None)) after connection broken by 'NewConnectionError('<urllib3.connection.HTTPSConnection object at 0x153b041143a0>: Failed to establish a new connection: [Errno -2] Name or service not known')': /api/5288891/store/
WARNING:urllib3.connectionpool:Retrying (Retry(total=1, connect=None, read=None, redirect=None, status=None)) after connection broken by 'NewConnectionError('<urllib3.connection.HTTPSConnection object at 0x153b04114280>: Failed to establish a new connection: [Errno -2] Name or service not known')': /api/5288891/store/
WARNING:urllib3.connectionpool:Retrying (Retry(total=0, connect=None, read=None, redirect=None, status=None)) after connection broken by 'NewConnectionError('<urllib3.connection.HTTPSConnection object at 0x153b041140d0>: Failed to establish a new connection: [Errno -2] Name or service not known')': /api/5288891/store/
WARNING:urllib3.connectionpool:Retrying (Retry(total=2, connect=None, read=None, redirect=None, status=None)) after connection broken by 'NewConnectionError('<urllib3.connection.HTTPSConnection object at 0x14e734b30d00>: Failed to establish a new connection: [Errno -2] Name or service not known')': /api/5288891/envelope/
WARNING:urllib3.connectionpool:Retrying (Retry(total=1, connect=None, read=None, redirect=None, status=None)) after connection broken by 'NewConnectionError('<urllib3.connection.HTTPSConnection object at 0x14e734b30970>: Failed to establish a new connection: [Errno -2] Name or service not known')': /api/5288891/envelope/
WARNING:urllib3.connectionpool:Retrying (Retry(total=0, connect=None, read=None, redirect=None, status=None)) after connection broken by 'NewConnectionError('<urllib3.connection.HTTPSConnection object at 0x14e734b310f0>: Failed to establish a new connection: [Errno -2] Name or service not known')': /api/5288891/envelope/
WARNING:urllib3.connectionpool:Retrying (Retry(total=2, connect=None, read=None, redirect=None, status=None)) after connection broken by 'NewConnectionError('<urllib3.connection.HTTPSConnection object at 0x14e734b308b0>: Failed to establish a new connection: [Errno -2] Name or service not known')': /api/5288891/store/
WARNING:urllib3.connectionpool:Retrying (Retry(total=1, connect=None, read=None, redirect=None, status=None)) after connection broken by 'NewConnectionError('<urllib3.connection.HTTPSConnection object at 0x14e734b30700>: Failed to establish a new connection: [Errno -2] Name or service not known')': /api/5288891/store/
WARNING:urllib3.connectionpool:Retrying (Retry(total=0, connect=None, read=None, redirect=None, status=None)) after connection broken by 'NewConnectionError('<urllib3.connection.HTTPSConnection object at 0x14e734b30550>: Failed to establish a new connection: [Errno -2] Name or service not known')': /api/5288891/store/
WARNING:urllib3.connectionpool:Retrying (Retry(total=2, connect=None, read=None, redirect=None, status=None)) after connection broken by 'NewConnectionError('<urllib3.connection.HTTPSConnection object at 0x14e734b303a0>: Failed to establish a new connection: [Errno -2] Name or service not known')': /api/5288891/store/
WARNING:urllib3.connectionpool:Retrying (Retry(total=1, connect=None, read=None, redirect=None, status=None)) after connection broken by 'NewConnectionError('<urllib3.connection.HTTPSConnection object at 0x14e734b30280>: Failed to establish a new connection: [Errno -2] Name or service not known')': /api/5288891/store/
WARNING:urllib3.connectionpool:Retrying (Retry(total=0, connect=None, read=None, redirect=None, status=None)) after connection broken by 'NewConnectionError('<urllib3.connection.HTTPSConnection object at 0x14e734b300d0>: Failed to establish a new connection: [Errno -2] Name or service not known')': /api/5288891/store/
wandb: ERROR Abnormal program exit
Traceback (most recent call last):
  File "/home/od2961/.conda/envs/similar-behavior/lib/python3.10/site-packages/wandb/sdk/wandb_init.py", line 1144, in init
    run = wi.init()
  File "/home/od2961/.conda/envs/similar-behavior/lib/python3.10/site-packages/wandb/sdk/wandb_init.py", line 773, in init
    raise error
wandb.errors.CommError: Error communicating with wandb process, exiting...
For more info see: https://docs.wandb.ai/guides/track/tracking-faq#initstarterror-error-communicating-with-wandb-process-

The above exception was the direct cause of the following exception:

Traceback (most recent call last):
  File "/scratch/gpfs/od2961/similarity-paper/similar-behavior/cleanrl/cleanrl/meow_continuous_action.py", line 432, in <module>
    train()
  File "/scratch/gpfs/od2961/similarity-paper/similar-behavior/cleanrl/cleanrl/meow_continuous_action.py", line 244, in train
    wandb.init(
  File "/home/od2961/.conda/envs/similar-behavior/lib/python3.10/site-packages/wandb/sdk/wandb_init.py", line 1181, in init
    raise Exception("problem") from error_seen
Exception: problem
wandb: ERROR Abnormal program exit
Traceback (most recent call last):
  File "/home/od2961/.conda/envs/similar-behavior/lib/python3.10/site-packages/wandb/sdk/wandb_init.py", line 1144, in init
    run = wi.init()
  File "/home/od2961/.conda/envs/similar-behavior/lib/python3.10/site-packages/wandb/sdk/wandb_init.py", line 773, in init
    raise error
wandb.errors.CommError: Error communicating with wandb process, exiting...
For more info see: https://docs.wandb.ai/guides/track/tracking-faq#initstarterror-error-communicating-with-wandb-process-

The above exception was the direct cause of the following exception:

Traceback (most recent call last):
  File "/scratch/gpfs/od2961/similarity-paper/similar-behavior/cleanrl/cleanrl/meow_continuous_action.py", line 432, in <module>
    train()
  File "/scratch/gpfs/od2961/similarity-paper/similar-behavior/cleanrl/cleanrl/meow_continuous_action.py", line 244, in train
    wandb.init(
  File "/home/od2961/.conda/envs/similar-behavior/lib/python3.10/site-packages/wandb/sdk/wandb_init.py", line 1181, in init
    raise Exception("problem") from error_seen
Exception: problem
Launching experiment meow_walker2d-v4-seed-1-alpha-0.6
Launching experiment meow_walker2d-v4-seed-1-alpha-0
/home/od2961/.conda/envs/similar-behavior/lib/python3.10/site-packages/pkg_resources/__init__.py:121: DeprecationWarning: pkg_resources is deprecated as an API
  warnings.warn("pkg_resources is deprecated as an API", DeprecationWarning)
/home/od2961/.conda/envs/similar-behavior/lib/python3.10/site-packages/pkg_resources/__init__.py:121: DeprecationWarning: pkg_resources is deprecated as an API
  warnings.warn("pkg_resources is deprecated as an API", DeprecationWarning)
/home/od2961/.conda/envs/similar-behavior/lib/python3.10/site-packages/pkg_resources/__init__.py:2870: DeprecationWarning: Deprecated call to `pkg_resources.declare_namespace('google')`.
Implementing implicit namespace packages (as specified in PEP 420) is preferred to `pkg_resources.declare_namespace`. See https://setuptools.pypa.io/en/latest/references/keywords.html#keyword-namespace-packages
  declare_namespace(pkg)
/home/od2961/.conda/envs/similar-behavior/lib/python3.10/site-packages/pkg_resources/__init__.py:2870: DeprecationWarning: Deprecated call to `pkg_resources.declare_namespace('mpl_toolkits')`.
Implementing implicit namespace packages (as specified in PEP 420) is preferred to `pkg_resources.declare_namespace`. See https://setuptools.pypa.io/en/latest/references/keywords.html#keyword-namespace-packages
  declare_namespace(pkg)
/home/od2961/.conda/envs/similar-behavior/lib/python3.10/site-packages/pkg_resources/__init__.py:2870: DeprecationWarning: Deprecated call to `pkg_resources.declare_namespace('google')`.
Implementing implicit namespace packages (as specified in PEP 420) is preferred to `pkg_resources.declare_namespace`. See https://setuptools.pypa.io/en/latest/references/keywords.html#keyword-namespace-packages
  declare_namespace(pkg)
/home/od2961/.conda/envs/similar-behavior/lib/python3.10/site-packages/pkg_resources/__init__.py:2870: DeprecationWarning: Deprecated call to `pkg_resources.declare_namespace('google')`.
Implementing implicit namespace packages (as specified in PEP 420) is preferred to `pkg_resources.declare_namespace`. See https://setuptools.pypa.io/en/latest/references/keywords.html#keyword-namespace-packages
  declare_namespace(pkg)
/home/od2961/.conda/envs/similar-behavior/lib/python3.10/site-packages/pkg_resources/__init__.py:2870: DeprecationWarning: Deprecated call to `pkg_resources.declare_namespace('mpl_toolkits')`.
Implementing implicit namespace packages (as specified in PEP 420) is preferred to `pkg_resources.declare_namespace`. See https://setuptools.pypa.io/en/latest/references/keywords.html#keyword-namespace-packages
  declare_namespace(pkg)
/home/od2961/.conda/envs/similar-behavior/lib/python3.10/site-packages/pkg_resources/__init__.py:2870: DeprecationWarning: Deprecated call to `pkg_resources.declare_namespace('google')`.
Implementing implicit namespace packages (as specified in PEP 420) is preferred to `pkg_resources.declare_namespace`. See https://setuptools.pypa.io/en/latest/references/keywords.html#keyword-namespace-packages
  declare_namespace(pkg)
wandb: Network error (ConnectionError), entering retry loop.
wandb: Network error (ConnectionError), entering retry loop.
wandb: W&B API key is configured. Use `wandb login --relogin` to force relogin
wandb: W&B API key is configured. Use `wandb login --relogin` to force relogin
wandb: - Waiting for wandb.init()...wandb: - Waiting for wandb.init()...wandb: \ Waiting for wandb.init()...wandb: \ Waiting for wandb.init()...wandb: | Waiting for wandb.init()...wandb: | Waiting for wandb.init()...wandb: Network error (ConnectionError), entering retry loop.
wandb: Network error (ConnectionError), entering retry loop.
wandb: / Waiting for wandb.init()...wandb: / Waiting for wandb.init()...wandb: - Waiting for wandb.init()...wandb: - Waiting for wandb.init()...wandb: \ Waiting for wandb.init()...wandb: \ Waiting for wandb.init()...wandb: | Waiting for wandb.init()...wandb: | Waiting for wandb.init()...wandb: / Waiting for wandb.init()...wandb: / Waiting for wandb.init()...wandb: - Waiting for wandb.init()...wandb: - Waiting for wandb.init()...wandb: \ Waiting for wandb.init()...wandb: \ Waiting for wandb.init()...wandb: | Waiting for wandb.init()...wandb: | Waiting for wandb.init()...wandb: / Waiting for wandb.init()...wandb: / Waiting for wandb.init()...wandb: - Waiting for wandb.init()...wandb: - Waiting for wandb.init()...wandb: \ Waiting for wandb.init()...wandb: \ Waiting for wandb.init()...wandb: | Waiting for wandb.init()...wandb: | Waiting for wandb.init()...wandb: / Waiting for wandb.init()...wandb: / Waiting for wandb.init()...wandb: - Waiting for wandb.init()...wandb: - Waiting for wandb.init()...wandb: \ Waiting for wandb.init()...wandb: \ Waiting for wandb.init()...wandb: | Waiting for wandb.init()...wandb: | Waiting for wandb.init()...wandb: / Waiting for wandb.init()...wandb: / Waiting for wandb.init()...wandb: - Waiting for wandb.init()...wandb: - Waiting for wandb.init()...wandb: \ Waiting for wandb.init()...wandb: \ Waiting for wandb.init()...wandb: | Waiting for wandb.init()...wandb: | Waiting for wandb.init()...wandb: / Waiting for wandb.init()...wandb: / Waiting for wandb.init()...wandb: - Waiting for wandb.init()...wandb: - Waiting for wandb.init()...wandb: \ Waiting for wandb.init()...wandb: \ Waiting for wandb.init()...wandb: | Waiting for wandb.init()...wandb: | Waiting for wandb.init()...wandb: / Waiting for wandb.init()...wandb: / Waiting for wandb.init()...wandb: - Waiting for wandb.init()...wandb: - Waiting for wandb.init()...wandb: \ Waiting for wandb.init()...wandb: \ Waiting for wandb.init()...wandb: | Waiting for wandb.init()...wandb: | Waiting for wandb.init()...wandb: / Waiting for wandb.init()...wandb: / Waiting for wandb.init()...wandb: - Waiting for wandb.init()...wandb: - Waiting for wandb.init()...wandb: \ Waiting for wandb.init()...wandb: \ Waiting for wandb.init()...wandb: | Waiting for wandb.init()...wandb: | Waiting for wandb.init()...wandb: / Waiting for wandb.init()...wandb: / Waiting for wandb.init()...wandb: - Waiting for wandb.init()...wandb: - Waiting for wandb.init()...wandb: \ Waiting for wandb.init()...wandb: \ Waiting for wandb.init()...wandb: | Waiting for wandb.init()...wandb: | Waiting for wandb.init()...wandb: / Waiting for wandb.init()...wandb: / Waiting for wandb.init()...wandb: - Waiting for wandb.init()...wandb: - Waiting for wandb.init()...wandb: \ Waiting for wandb.init()...wandb: \ Waiting for wandb.init()...wandb: | Waiting for wandb.init()...wandb: | Waiting for wandb.init()...wandb: / Waiting for wandb.init()...wandb: / Waiting for wandb.init()...wandb: - Waiting for wandb.init()...wandb: - Waiting for wandb.init()...wandb: \ Waiting for wandb.init()...wandb: \ Waiting for wandb.init()...wandb: | Waiting for wandb.init()...wandb: | Waiting for wandb.init()...wandb: / Waiting for wandb.init()...wandb: / Waiting for wandb.init()...wandb: - Waiting for wandb.init()...wandb: - Waiting for wandb.init()...wandb: \ Waiting for wandb.init()...wandb: \ Waiting for wandb.init()...wandb: | Waiting for wandb.init()...wandb: | Waiting for wandb.init()...wandb: / Waiting for wandb.init()...wandb: / Waiting for wandb.init()...wandb: - Waiting for wandb.init()...wandb: - Waiting for wandb.init()...wandb: \ Waiting for wandb.init()...wandb: \ Waiting for wandb.init()...wandb: | Waiting for wandb.init()...wandb: | Waiting for wandb.init()...wandb: / Waiting for wandb.init()...wandb: / Waiting for wandb.init()...wandb: - Waiting for wandb.init()...wandb: - Waiting for wandb.init()...wandb: \ Waiting for wandb.init()...wandb: \ Waiting for wandb.init()...wandb: | Waiting for wandb.init()...wandb: | Waiting for wandb.init()...Problem at: /scratch/gpfs/od2961/similarity-paper/similar-behavior/cleanrl/cleanrl/meow_continuous_action.py 244 train
Traceback (most recent call last):
  File "/home/od2961/.conda/envs/similar-behavior/lib/python3.10/site-packages/wandb/sdk/wandb_init.py", line 1144, in init
    run = wi.init()
  File "/home/od2961/.conda/envs/similar-behavior/lib/python3.10/site-packages/wandb/sdk/wandb_init.py", line 773, in init
    raise error
wandb.errors.CommError: Error communicating with wandb process, exiting...
For more info see: https://docs.wandb.ai/guides/track/tracking-faq#initstarterror-error-communicating-with-wandb-process-
WARNING:urllib3.connectionpool:Retrying (Retry(total=2, connect=None, read=None, redirect=None, status=None)) after connection broken by 'NewConnectionError('<urllib3.connection.HTTPSConnection object at 0x147759cb4f10>: Failed to establish a new connection: [Errno -2] Name or service not known')': /api/5288891/store/
WARNING:urllib3.connectionpool:Retrying (Retry(total=1, connect=None, read=None, redirect=None, status=None)) after connection broken by 'NewConnectionError('<urllib3.connection.HTTPSConnection object at 0x147759cb4b80>: Failed to establish a new connection: [Errno -2] Name or service not known')': /api/5288891/store/
WARNING:urllib3.connectionpool:Retrying (Retry(total=0, connect=None, read=None, redirect=None, status=None)) after connection broken by 'NewConnectionError('<urllib3.connection.HTTPSConnection object at 0x147759cb4a90>: Failed to establish a new connection: [Errno -2] Name or service not known')': /api/5288891/store/
WARNING:urllib3.connectionpool:Retrying (Retry(total=2, connect=None, read=None, redirect=None, status=None)) after connection broken by 'NewConnectionError('<urllib3.connection.HTTPSConnection object at 0x147759cb5030>: Failed to establish a new connection: [Errno -2] Name or service not known')': /api/5288891/store/
WARNING:urllib3.connectionpool:Retrying (Retry(total=1, connect=None, read=None, redirect=None, status=None)) after connection broken by 'NewConnectionError('<urllib3.connection.HTTPSConnection object at 0x147759cb49a0>: Failed to establish a new connection: [Errno -2] Name or service not known')': /api/5288891/store/
WARNING:urllib3.connectionpool:Retrying (Retry(total=0, connect=None, read=None, redirect=None, status=None)) after connection broken by 'NewConnectionError('<urllib3.connection.HTTPSConnection object at 0x147759cb47f0>: Failed to establish a new connection: [Errno -2] Name or service not known')': /api/5288891/store/
Problem at: /scratch/gpfs/od2961/similarity-paper/similar-behavior/cleanrl/cleanrl/meow_continuous_action.py 244 train
Traceback (most recent call last):
  File "/home/od2961/.conda/envs/similar-behavior/lib/python3.10/site-packages/wandb/sdk/wandb_init.py", line 1144, in init
    run = wi.init()
  File "/home/od2961/.conda/envs/similar-behavior/lib/python3.10/site-packages/wandb/sdk/wandb_init.py", line 773, in init
    raise error
wandb.errors.CommError: Error communicating with wandb process, exiting...
For more info see: https://docs.wandb.ai/guides/track/tracking-faq#initstarterror-error-communicating-with-wandb-process-
WARNING:urllib3.connectionpool:Retrying (Retry(total=2, connect=None, read=None, redirect=None, status=None)) after connection broken by 'NewConnectionError('<urllib3.connection.HTTPSConnection object at 0x149fbfaa0f10>: Failed to establish a new connection: [Errno -2] Name or service not known')': /api/5288891/store/
WARNING:urllib3.connectionpool:Retrying (Retry(total=1, connect=None, read=None, redirect=None, status=None)) after connection broken by 'NewConnectionError('<urllib3.connection.HTTPSConnection object at 0x149fbfaa0b80>: Failed to establish a new connection: [Errno -2] Name or service not known')': /api/5288891/store/
WARNING:urllib3.connectionpool:Retrying (Retry(total=0, connect=None, read=None, redirect=None, status=None)) after connection broken by 'NewConnectionError('<urllib3.connection.HTTPSConnection object at 0x149fbfaa3e50>: Failed to establish a new connection: [Errno -2] Name or service not known')': /api/5288891/store/
WARNING:urllib3.connectionpool:Retrying (Retry(total=2, connect=None, read=None, redirect=None, status=None)) after connection broken by 'NewConnectionError('<urllib3.connection.HTTPSConnection object at 0x149fbfaa0fd0>: Failed to establish a new connection: [Errno -2] Name or service not known')': /api/5288891/store/
WARNING:urllib3.connectionpool:Retrying (Retry(total=1, connect=None, read=None, redirect=None, status=None)) after connection broken by 'NewConnectionError('<urllib3.connection.HTTPSConnection object at 0x149fbfaa09a0>: Failed to establish a new connection: [Errno -2] Name or service not known')': /api/5288891/store/
WARNING:urllib3.connectionpool:Retrying (Retry(total=0, connect=None, read=None, redirect=None, status=None)) after connection broken by 'NewConnectionError('<urllib3.connection.HTTPSConnection object at 0x149fbfaa07f0>: Failed to establish a new connection: [Errno -2] Name or service not known')': /api/5288891/store/
WARNING:urllib3.connectionpool:Retrying (Retry(total=2, connect=None, read=None, redirect=None, status=None)) after connection broken by 'NewConnectionError('<urllib3.connection.HTTPSConnection object at 0x147759cb43a0>: Failed to establish a new connection: [Errno -2] Name or service not known')': /api/5288891/envelope/
WARNING:urllib3.connectionpool:Retrying (Retry(total=1, connect=None, read=None, redirect=None, status=None)) after connection broken by 'NewConnectionError('<urllib3.connection.HTTPSConnection object at 0x147759cb4100>: Failed to establish a new connection: [Errno -2] Name or service not known')': /api/5288891/envelope/
WARNING:urllib3.connectionpool:Retrying (Retry(total=0, connect=None, read=None, redirect=None, status=None)) after connection broken by 'NewConnectionError('<urllib3.connection.HTTPSConnection object at 0x14775a0b27d0>: Failed to establish a new connection: [Errno -2] Name or service not known')': /api/5288891/envelope/
WARNING:urllib3.connectionpool:Retrying (Retry(total=2, connect=None, read=None, redirect=None, status=None)) after connection broken by 'NewConnectionError('<urllib3.connection.HTTPSConnection object at 0x149fbfaa03a0>: Failed to establish a new connection: [Errno -2] Name or service not known')': /api/5288891/envelope/
WARNING:urllib3.connectionpool:Retrying (Retry(total=1, connect=None, read=None, redirect=None, status=None)) after connection broken by 'NewConnectionError('<urllib3.connection.HTTPSConnection object at 0x149fbfaa0100>: Failed to establish a new connection: [Errno -2] Name or service not known')': /api/5288891/envelope/
WARNING:urllib3.connectionpool:Retrying (Retry(total=0, connect=None, read=None, redirect=None, status=None)) after connection broken by 'NewConnectionError('<urllib3.connection.HTTPSConnection object at 0x149fbfea27d0>: Failed to establish a new connection: [Errno -2] Name or service not known')': /api/5288891/envelope/
wandb: ERROR Abnormal program exit
Traceback (most recent call last):
  File "/home/od2961/.conda/envs/similar-behavior/lib/python3.10/site-packages/wandb/sdk/wandb_init.py", line 1144, in init
    run = wi.init()
  File "/home/od2961/.conda/envs/similar-behavior/lib/python3.10/site-packages/wandb/sdk/wandb_init.py", line 773, in init
    raise error
wandb.errors.CommError: Error communicating with wandb process, exiting...
For more info see: https://docs.wandb.ai/guides/track/tracking-faq#initstarterror-error-communicating-with-wandb-process-

The above exception was the direct cause of the following exception:

Traceback (most recent call last):
  File "/scratch/gpfs/od2961/similarity-paper/similar-behavior/cleanrl/cleanrl/meow_continuous_action.py", line 432, in <module>
    train()
  File "/scratch/gpfs/od2961/similarity-paper/similar-behavior/cleanrl/cleanrl/meow_continuous_action.py", line 244, in train
    wandb.init(
  File "/home/od2961/.conda/envs/similar-behavior/lib/python3.10/site-packages/wandb/sdk/wandb_init.py", line 1181, in init
    raise Exception("problem") from error_seen
Exception: problem
wandb: ERROR Abnormal program exit
Traceback (most recent call last):
  File "/home/od2961/.conda/envs/similar-behavior/lib/python3.10/site-packages/wandb/sdk/wandb_init.py", line 1144, in init
    run = wi.init()
  File "/home/od2961/.conda/envs/similar-behavior/lib/python3.10/site-packages/wandb/sdk/wandb_init.py", line 773, in init
    raise error
wandb.errors.CommError: Error communicating with wandb process, exiting...
For more info see: https://docs.wandb.ai/guides/track/tracking-faq#initstarterror-error-communicating-with-wandb-process-

The above exception was the direct cause of the following exception:

Traceback (most recent call last):
  File "/scratch/gpfs/od2961/similarity-paper/similar-behavior/cleanrl/cleanrl/meow_continuous_action.py", line 432, in <module>
    train()
  File "/scratch/gpfs/od2961/similarity-paper/similar-behavior/cleanrl/cleanrl/meow_continuous_action.py", line 244, in train
    wandb.init(
  File "/home/od2961/.conda/envs/similar-behavior/lib/python3.10/site-packages/wandb/sdk/wandb_init.py", line 1181, in init
    raise Exception("problem") from error_seen
Exception: problem
Launching experiment meow_walker2d-v4-seed-1-alpha-0.1
Launching experiment meow_walker2d-v4-seed-2-alpha-0.2
/home/od2961/.conda/envs/similar-behavior/lib/python3.10/site-packages/pkg_resources/__init__.py:121: DeprecationWarning: pkg_resources is deprecated as an API
  warnings.warn("pkg_resources is deprecated as an API", DeprecationWarning)
/home/od2961/.conda/envs/similar-behavior/lib/python3.10/site-packages/pkg_resources/__init__.py:121: DeprecationWarning: pkg_resources is deprecated as an API
  warnings.warn("pkg_resources is deprecated as an API", DeprecationWarning)
/home/od2961/.conda/envs/similar-behavior/lib/python3.10/site-packages/pkg_resources/__init__.py:2870: DeprecationWarning: Deprecated call to `pkg_resources.declare_namespace('google')`.
Implementing implicit namespace packages (as specified in PEP 420) is preferred to `pkg_resources.declare_namespace`. See https://setuptools.pypa.io/en/latest/references/keywords.html#keyword-namespace-packages
  declare_namespace(pkg)
/home/od2961/.conda/envs/similar-behavior/lib/python3.10/site-packages/pkg_resources/__init__.py:2870: DeprecationWarning: Deprecated call to `pkg_resources.declare_namespace('mpl_toolkits')`.
Implementing implicit namespace packages (as specified in PEP 420) is preferred to `pkg_resources.declare_namespace`. See https://setuptools.pypa.io/en/latest/references/keywords.html#keyword-namespace-packages
  declare_namespace(pkg)
/home/od2961/.conda/envs/similar-behavior/lib/python3.10/site-packages/pkg_resources/__init__.py:2870: DeprecationWarning: Deprecated call to `pkg_resources.declare_namespace('google')`.
Implementing implicit namespace packages (as specified in PEP 420) is preferred to `pkg_resources.declare_namespace`. See https://setuptools.pypa.io/en/latest/references/keywords.html#keyword-namespace-packages
  declare_namespace(pkg)
/home/od2961/.conda/envs/similar-behavior/lib/python3.10/site-packages/pkg_resources/__init__.py:2870: DeprecationWarning: Deprecated call to `pkg_resources.declare_namespace('google')`.
Implementing implicit namespace packages (as specified in PEP 420) is preferred to `pkg_resources.declare_namespace`. See https://setuptools.pypa.io/en/latest/references/keywords.html#keyword-namespace-packages
  declare_namespace(pkg)
/home/od2961/.conda/envs/similar-behavior/lib/python3.10/site-packages/pkg_resources/__init__.py:2870: DeprecationWarning: Deprecated call to `pkg_resources.declare_namespace('mpl_toolkits')`.
Implementing implicit namespace packages (as specified in PEP 420) is preferred to `pkg_resources.declare_namespace`. See https://setuptools.pypa.io/en/latest/references/keywords.html#keyword-namespace-packages
  declare_namespace(pkg)
/home/od2961/.conda/envs/similar-behavior/lib/python3.10/site-packages/pkg_resources/__init__.py:2870: DeprecationWarning: Deprecated call to `pkg_resources.declare_namespace('google')`.
Implementing implicit namespace packages (as specified in PEP 420) is preferred to `pkg_resources.declare_namespace`. See https://setuptools.pypa.io/en/latest/references/keywords.html#keyword-namespace-packages
  declare_namespace(pkg)
wandb: Network error (ConnectionError), entering retry loop.
wandb: Network error (ConnectionError), entering retry loop.
wandb: W&B API key is configured. Use `wandb login --relogin` to force relogin
wandb: W&B API key is configured. Use `wandb login --relogin` to force relogin
wandb: - Waiting for wandb.init()...wandb: - Waiting for wandb.init()...wandb: \ Waiting for wandb.init()...wandb: \ Waiting for wandb.init()...wandb: | Waiting for wandb.init()...wandb: | Waiting for wandb.init()...wandb: Network error (ConnectionError), entering retry loop.
wandb: Network error (ConnectionError), entering retry loop.
wandb: / Waiting for wandb.init()...wandb: / Waiting for wandb.init()...wandb: - Waiting for wandb.init()...wandb: - Waiting for wandb.init()...wandb: \ Waiting for wandb.init()...wandb: \ Waiting for wandb.init()...wandb: | Waiting for wandb.init()...wandb: | Waiting for wandb.init()...wandb: / Waiting for wandb.init()...wandb: / Waiting for wandb.init()...wandb: - Waiting for wandb.init()...wandb: - Waiting for wandb.init()...wandb: \ Waiting for wandb.init()...wandb: \ Waiting for wandb.init()...wandb: | Waiting for wandb.init()...wandb: | Waiting for wandb.init()...wandb: / Waiting for wandb.init()...wandb: / Waiting for wandb.init()...wandb: - Waiting for wandb.init()...wandb: - Waiting for wandb.init()...wandb: \ Waiting for wandb.init()...wandb: \ Waiting for wandb.init()...wandb: | Waiting for wandb.init()...wandb: | Waiting for wandb.init()...wandb: / Waiting for wandb.init()...wandb: / Waiting for wandb.init()...wandb: - Waiting for wandb.init()...wandb: - Waiting for wandb.init()...wandb: \ Waiting for wandb.init()...wandb: \ Waiting for wandb.init()...wandb: | Waiting for wandb.init()...wandb: | Waiting for wandb.init()...wandb: / Waiting for wandb.init()...wandb: / Waiting for wandb.init()...wandb: - Waiting for wandb.init()...wandb: - Waiting for wandb.init()...wandb: \ Waiting for wandb.init()...wandb: \ Waiting for wandb.init()...wandb: | Waiting for wandb.init()...wandb: | Waiting for wandb.init()...wandb: / Waiting for wandb.init()...wandb: / Waiting for wandb.init()...wandb: - Waiting for wandb.init()...wandb: - Waiting for wandb.init()...wandb: \ Waiting for wandb.init()...wandb: \ Waiting for wandb.init()...wandb: | Waiting for wandb.init()...wandb: | Waiting for wandb.init()...wandb: / Waiting for wandb.init()...wandb: / Waiting for wandb.init()...wandb: - Waiting for wandb.init()...wandb: - Waiting for wandb.init()...wandb: \ Waiting for wandb.init()...wandb: \ Waiting for wandb.init()...wandb: | Waiting for wandb.init()...wandb: | Waiting for wandb.init()...wandb: / Waiting for wandb.init()...wandb: / Waiting for wandb.init()...wandb: - Waiting for wandb.init()...wandb: - Waiting for wandb.init()...wandb: \ Waiting for wandb.init()...wandb: \ Waiting for wandb.init()...wandb: | Waiting for wandb.init()...wandb: | Waiting for wandb.init()...wandb: / Waiting for wandb.init()...wandb: / Waiting for wandb.init()...wandb: - Waiting for wandb.init()...wandb: - Waiting for wandb.init()...wandb: \ Waiting for wandb.init()...wandb: \ Waiting for wandb.init()...wandb: | Waiting for wandb.init()...wandb: | Waiting for wandb.init()...wandb: / Waiting for wandb.init()...wandb: / Waiting for wandb.init()...wandb: - Waiting for wandb.init()...wandb: - Waiting for wandb.init()...wandb: \ Waiting for wandb.init()...wandb: \ Waiting for wandb.init()...wandb: | Waiting for wandb.init()...wandb: | Waiting for wandb.init()...wandb: / Waiting for wandb.init()...wandb: / Waiting for wandb.init()...wandb: - Waiting for wandb.init()...wandb: - Waiting for wandb.init()...wandb: \ Waiting for wandb.init()...wandb: \ Waiting for wandb.init()...wandb: | Waiting for wandb.init()...wandb: | Waiting for wandb.init()...wandb: / Waiting for wandb.init()...wandb: / Waiting for wandb.init()...wandb: - Waiting for wandb.init()...wandb: - Waiting for wandb.init()...wandb: \ Waiting for wandb.init()...wandb: \ Waiting for wandb.init()...wandb: | Waiting for wandb.init()...wandb: | Waiting for wandb.init()...wandb: / Waiting for wandb.init()...wandb: / Waiting for wandb.init()...wandb: - Waiting for wandb.init()...wandb: - Waiting for wandb.init()...wandb: \ Waiting for wandb.init()...wandb: \ Waiting for wandb.init()...wandb: | Waiting for wandb.init()...wandb: | Waiting for wandb.init()...wandb: / Waiting for wandb.init()...wandb: / Waiting for wandb.init()...wandb: - Waiting for wandb.init()...wandb: - Waiting for wandb.init()...wandb: \ Waiting for wandb.init()...wandb: \ Waiting for wandb.init()...wandb: | Waiting for wandb.init()...wandb: | Waiting for wandb.init()...Problem at: /scratch/gpfs/od2961/similarity-paper/similar-behavior/cleanrl/cleanrl/meow_continuous_action.py 244 train
Traceback (most recent call last):
  File "/home/od2961/.conda/envs/similar-behavior/lib/python3.10/site-packages/wandb/sdk/wandb_init.py", line 1144, in init
    run = wi.init()
  File "/home/od2961/.conda/envs/similar-behavior/lib/python3.10/site-packages/wandb/sdk/wandb_init.py", line 773, in init
    raise error
wandb.errors.CommError: Error communicating with wandb process, exiting...
For more info see: https://docs.wandb.ai/guides/track/tracking-faq#initstarterror-error-communicating-with-wandb-process-
Problem at: /scratch/gpfs/od2961/similarity-paper/similar-behavior/cleanrl/cleanrl/meow_continuous_action.py 244 train
Traceback (most recent call last):
  File "/home/od2961/.conda/envs/similar-behavior/lib/python3.10/site-packages/wandb/sdk/wandb_init.py", line 1144, in init
    run = wi.init()
  File "/home/od2961/.conda/envs/similar-behavior/lib/python3.10/site-packages/wandb/sdk/wandb_init.py", line 773, in init
    raise error
wandb.errors.CommError: Error communicating with wandb process, exiting...
For more info see: https://docs.wandb.ai/guides/track/tracking-faq#initstarterror-error-communicating-with-wandb-process-
WARNING:urllib3.connectionpool:Retrying (Retry(total=2, connect=None, read=None, redirect=None, status=None)) after connection broken by 'NewConnectionError('<urllib3.connection.HTTPSConnection object at 0x14a712edcc40>: Failed to establish a new connection: [Errno -2] Name or service not known')': /api/5288891/envelope/
WARNING:urllib3.connectionpool:Retrying (Retry(total=1, connect=None, read=None, redirect=None, status=None)) after connection broken by 'NewConnectionError('<urllib3.connection.HTTPSConnection object at 0x14a712edc970>: Failed to establish a new connection: [Errno -2] Name or service not known')': /api/5288891/envelope/
WARNING:urllib3.connectionpool:Retrying (Retry(total=0, connect=None, read=None, redirect=None, status=None)) after connection broken by 'NewConnectionError('<urllib3.connection.HTTPSConnection object at 0x14a712edd1e0>: Failed to establish a new connection: [Errno -2] Name or service not known')': /api/5288891/envelope/
WARNING:urllib3.connectionpool:Retrying (Retry(total=2, connect=None, read=None, redirect=None, status=None)) after connection broken by 'NewConnectionError('<urllib3.connection.HTTPSConnection object at 0x14a712edc8b0>: Failed to establish a new connection: [Errno -2] Name or service not known')': /api/5288891/store/
WARNING:urllib3.connectionpool:Retrying (Retry(total=1, connect=None, read=None, redirect=None, status=None)) after connection broken by 'NewConnectionError('<urllib3.connection.HTTPSConnection object at 0x14a712edc640>: Failed to establish a new connection: [Errno -2] Name or service not known')': /api/5288891/store/
WARNING:urllib3.connectionpool:Retrying (Retry(total=0, connect=None, read=None, redirect=None, status=None)) after connection broken by 'NewConnectionError('<urllib3.connection.HTTPSConnection object at 0x14a712edc550>: Failed to establish a new connection: [Errno -2] Name or service not known')': /api/5288891/store/
WARNING:urllib3.connectionpool:Retrying (Retry(total=2, connect=None, read=None, redirect=None, status=None)) after connection broken by 'NewConnectionError('<urllib3.connection.HTTPSConnection object at 0x14a712edc460>: Failed to establish a new connection: [Errno -2] Name or service not known')': /api/5288891/store/
WARNING:urllib3.connectionpool:Retrying (Retry(total=1, connect=None, read=None, redirect=None, status=None)) after connection broken by 'NewConnectionError('<urllib3.connection.HTTPSConnection object at 0x14a712edc1c0>: Failed to establish a new connection: [Errno -2] Name or service not known')': /api/5288891/store/
WARNING:urllib3.connectionpool:Retrying (Retry(total=0, connect=None, read=None, redirect=None, status=None)) after connection broken by 'NewConnectionError('<urllib3.connection.HTTPSConnection object at 0x14a712edc0d0>: Failed to establish a new connection: [Errno -2] Name or service not known')': /api/5288891/store/
WARNING:urllib3.connectionpool:Retrying (Retry(total=2, connect=None, read=None, redirect=None, status=None)) after connection broken by 'NewConnectionError('<urllib3.connection.HTTPSConnection object at 0x151eed8b8cd0>: Failed to establish a new connection: [Errno -2] Name or service not known')': /api/5288891/envelope/
WARNING:urllib3.connectionpool:Retrying (Retry(total=1, connect=None, read=None, redirect=None, status=None)) after connection broken by 'NewConnectionError('<urllib3.connection.HTTPSConnection object at 0x151eed8b9120>: Failed to establish a new connection: [Errno -2] Name or service not known')': /api/5288891/envelope/
WARNING:urllib3.connectionpool:Retrying (Retry(total=0, connect=None, read=None, redirect=None, status=None)) after connection broken by 'NewConnectionError('<urllib3.connection.HTTPSConnection object at 0x151eed8b9000>: Failed to establish a new connection: [Errno -2] Name or service not known')': /api/5288891/envelope/
WARNING:urllib3.connectionpool:Retrying (Retry(total=2, connect=None, read=None, redirect=None, status=None)) after connection broken by 'NewConnectionError('<urllib3.connection.HTTPSConnection object at 0x151eed8b8940>: Failed to establish a new connection: [Errno -2] Name or service not known')': /api/5288891/store/
WARNING:urllib3.connectionpool:Retrying (Retry(total=1, connect=None, read=None, redirect=None, status=None)) after connection broken by 'NewConnectionError('<urllib3.connection.HTTPSConnection object at 0x151eed8b86d0>: Failed to establish a new connection: [Errno -2] Name or service not known')': /api/5288891/store/
WARNING:urllib3.connectionpool:Retrying (Retry(total=0, connect=None, read=None, redirect=None, status=None)) after connection broken by 'NewConnectionError('<urllib3.connection.HTTPSConnection object at 0x151eed8b8520>: Failed to establish a new connection: [Errno -2] Name or service not known')': /api/5288891/store/
WARNING:urllib3.connectionpool:Retrying (Retry(total=2, connect=None, read=None, redirect=None, status=None)) after connection broken by 'NewConnectionError('<urllib3.connection.HTTPSConnection object at 0x151eed8b8430>: Failed to establish a new connection: [Errno -2] Name or service not known')': /api/5288891/store/
WARNING:urllib3.connectionpool:Retrying (Retry(total=1, connect=None, read=None, redirect=None, status=None)) after connection broken by 'NewConnectionError('<urllib3.connection.HTTPSConnection object at 0x151eed8b8250>: Failed to establish a new connection: [Errno -2] Name or service not known')': /api/5288891/store/
WARNING:urllib3.connectionpool:Retrying (Retry(total=0, connect=None, read=None, redirect=None, status=None)) after connection broken by 'NewConnectionError('<urllib3.connection.HTTPSConnection object at 0x151eed8b80a0>: Failed to establish a new connection: [Errno -2] Name or service not known')': /api/5288891/store/
wandb: ERROR Abnormal program exit
Traceback (most recent call last):
  File "/home/od2961/.conda/envs/similar-behavior/lib/python3.10/site-packages/wandb/sdk/wandb_init.py", line 1144, in init
    run = wi.init()
  File "/home/od2961/.conda/envs/similar-behavior/lib/python3.10/site-packages/wandb/sdk/wandb_init.py", line 773, in init
    raise error
wandb.errors.CommError: Error communicating with wandb process, exiting...
For more info see: https://docs.wandb.ai/guides/track/tracking-faq#initstarterror-error-communicating-with-wandb-process-

The above exception was the direct cause of the following exception:

Traceback (most recent call last):
  File "/scratch/gpfs/od2961/similarity-paper/similar-behavior/cleanrl/cleanrl/meow_continuous_action.py", line 432, in <module>
    train()
  File "/scratch/gpfs/od2961/similarity-paper/similar-behavior/cleanrl/cleanrl/meow_continuous_action.py", line 244, in train
    wandb.init(
  File "/home/od2961/.conda/envs/similar-behavior/lib/python3.10/site-packages/wandb/sdk/wandb_init.py", line 1181, in init
    raise Exception("problem") from error_seen
Exception: problem
wandb: ERROR Abnormal program exit
Traceback (most recent call last):
  File "/home/od2961/.conda/envs/similar-behavior/lib/python3.10/site-packages/wandb/sdk/wandb_init.py", line 1144, in init
    run = wi.init()
  File "/home/od2961/.conda/envs/similar-behavior/lib/python3.10/site-packages/wandb/sdk/wandb_init.py", line 773, in init
    raise error
wandb.errors.CommError: Error communicating with wandb process, exiting...
For more info see: https://docs.wandb.ai/guides/track/tracking-faq#initstarterror-error-communicating-with-wandb-process-

The above exception was the direct cause of the following exception:

Traceback (most recent call last):
  File "/scratch/gpfs/od2961/similarity-paper/similar-behavior/cleanrl/cleanrl/meow_continuous_action.py", line 432, in <module>
    train()
  File "/scratch/gpfs/od2961/similarity-paper/similar-behavior/cleanrl/cleanrl/meow_continuous_action.py", line 244, in train
    wandb.init(
  File "/home/od2961/.conda/envs/similar-behavior/lib/python3.10/site-packages/wandb/sdk/wandb_init.py", line 1181, in init
    raise Exception("problem") from error_seen
Exception: problem
Launching experiment meow_walker2d-v4-seed-2-alpha-0.3
Launching experiment meow_walker2d-v4-seed-2-alpha-0.4
/home/od2961/.conda/envs/similar-behavior/lib/python3.10/site-packages/pkg_resources/__init__.py:121: DeprecationWarning: pkg_resources is deprecated as an API
  warnings.warn("pkg_resources is deprecated as an API", DeprecationWarning)
/home/od2961/.conda/envs/similar-behavior/lib/python3.10/site-packages/pkg_resources/__init__.py:121: DeprecationWarning: pkg_resources is deprecated as an API
  warnings.warn("pkg_resources is deprecated as an API", DeprecationWarning)
/home/od2961/.conda/envs/similar-behavior/lib/python3.10/site-packages/pkg_resources/__init__.py:2870: DeprecationWarning: Deprecated call to `pkg_resources.declare_namespace('google')`.
Implementing implicit namespace packages (as specified in PEP 420) is preferred to `pkg_resources.declare_namespace`. See https://setuptools.pypa.io/en/latest/references/keywords.html#keyword-namespace-packages
  declare_namespace(pkg)
/home/od2961/.conda/envs/similar-behavior/lib/python3.10/site-packages/pkg_resources/__init__.py:2870: DeprecationWarning: Deprecated call to `pkg_resources.declare_namespace('mpl_toolkits')`.
Implementing implicit namespace packages (as specified in PEP 420) is preferred to `pkg_resources.declare_namespace`. See https://setuptools.pypa.io/en/latest/references/keywords.html#keyword-namespace-packages
  declare_namespace(pkg)
/home/od2961/.conda/envs/similar-behavior/lib/python3.10/site-packages/pkg_resources/__init__.py:2870: DeprecationWarning: Deprecated call to `pkg_resources.declare_namespace('google')`.
Implementing implicit namespace packages (as specified in PEP 420) is preferred to `pkg_resources.declare_namespace`. See https://setuptools.pypa.io/en/latest/references/keywords.html#keyword-namespace-packages
  declare_namespace(pkg)
/home/od2961/.conda/envs/similar-behavior/lib/python3.10/site-packages/pkg_resources/__init__.py:2870: DeprecationWarning: Deprecated call to `pkg_resources.declare_namespace('google')`.
Implementing implicit namespace packages (as specified in PEP 420) is preferred to `pkg_resources.declare_namespace`. See https://setuptools.pypa.io/en/latest/references/keywords.html#keyword-namespace-packages
  declare_namespace(pkg)
/home/od2961/.conda/envs/similar-behavior/lib/python3.10/site-packages/pkg_resources/__init__.py:2870: DeprecationWarning: Deprecated call to `pkg_resources.declare_namespace('mpl_toolkits')`.
Implementing implicit namespace packages (as specified in PEP 420) is preferred to `pkg_resources.declare_namespace`. See https://setuptools.pypa.io/en/latest/references/keywords.html#keyword-namespace-packages
  declare_namespace(pkg)
/home/od2961/.conda/envs/similar-behavior/lib/python3.10/site-packages/pkg_resources/__init__.py:2870: DeprecationWarning: Deprecated call to `pkg_resources.declare_namespace('google')`.
Implementing implicit namespace packages (as specified in PEP 420) is preferred to `pkg_resources.declare_namespace`. See https://setuptools.pypa.io/en/latest/references/keywords.html#keyword-namespace-packages
  declare_namespace(pkg)
wandb: Network error (ConnectionError), entering retry loop.
wandb: Network error (ConnectionError), entering retry loop.
wandb: W&B API key is configured. Use `wandb login --relogin` to force relogin
wandb: W&B API key is configured. Use `wandb login --relogin` to force relogin
wandb: - Waiting for wandb.init()...wandb: - Waiting for wandb.init()...wandb: \ Waiting for wandb.init()...wandb: \ Waiting for wandb.init()...wandb: | Waiting for wandb.init()...wandb: | Waiting for wandb.init()...wandb: Network error (ConnectionError), entering retry loop.
wandb: Network error (ConnectionError), entering retry loop.
wandb: / Waiting for wandb.init()...wandb: / Waiting for wandb.init()...wandb: - Waiting for wandb.init()...wandb: - Waiting for wandb.init()...wandb: \ Waiting for wandb.init()...wandb: \ Waiting for wandb.init()...wandb: | Waiting for wandb.init()...wandb: | Waiting for wandb.init()...wandb: / Waiting for wandb.init()...wandb: / Waiting for wandb.init()...wandb: - Waiting for wandb.init()...wandb: - Waiting for wandb.init()...wandb: \ Waiting for wandb.init()...wandb: \ Waiting for wandb.init()...wandb: | Waiting for wandb.init()...wandb: | Waiting for wandb.init()...wandb: / Waiting for wandb.init()...wandb: / Waiting for wandb.init()...wandb: - Waiting for wandb.init()...wandb: - Waiting for wandb.init()...wandb: \ Waiting for wandb.init()...wandb: \ Waiting for wandb.init()...wandb: | Waiting for wandb.init()...wandb: | Waiting for wandb.init()...wandb: / Waiting for wandb.init()...wandb: / Waiting for wandb.init()...wandb: - Waiting for wandb.init()...wandb: - Waiting for wandb.init()...wandb: \ Waiting for wandb.init()...wandb: \ Waiting for wandb.init()...wandb: | Waiting for wandb.init()...wandb: | Waiting for wandb.init()...wandb: / Waiting for wandb.init()...wandb: / Waiting for wandb.init()...wandb: - Waiting for wandb.init()...wandb: - Waiting for wandb.init()...wandb: \ Waiting for wandb.init()...wandb: \ Waiting for wandb.init()...wandb: | Waiting for wandb.init()...wandb: | Waiting for wandb.init()...wandb: / Waiting for wandb.init()...wandb: / Waiting for wandb.init()...wandb: - Waiting for wandb.init()...wandb: - Waiting for wandb.init()...wandb: \ Waiting for wandb.init()...wandb: \ Waiting for wandb.init()...wandb: | Waiting for wandb.init()...wandb: | Waiting for wandb.init()...wandb: / Waiting for wandb.init()...wandb: / Waiting for wandb.init()...wandb: - Waiting for wandb.init()...wandb: - Waiting for wandb.init()...wandb: \ Waiting for wandb.init()...wandb: \ Waiting for wandb.init()...wandb: | Waiting for wandb.init()...wandb: | Waiting for wandb.init()...wandb: / Waiting for wandb.init()...wandb: / Waiting for wandb.init()...wandb: - Waiting for wandb.init()...wandb: - Waiting for wandb.init()...wandb: \ Waiting for wandb.init()...wandb: \ Waiting for wandb.init()...wandb: | Waiting for wandb.init()...wandb: | Waiting for wandb.init()...wandb: / Waiting for wandb.init()...wandb: / Waiting for wandb.init()...wandb: - Waiting for wandb.init()...wandb: - Waiting for wandb.init()...wandb: \ Waiting for wandb.init()...wandb: \ Waiting for wandb.init()...wandb: | Waiting for wandb.init()...wandb: | Waiting for wandb.init()...wandb: / Waiting for wandb.init()...wandb: / Waiting for wandb.init()...wandb: - Waiting for wandb.init()...wandb: - Waiting for wandb.init()...wandb: \ Waiting for wandb.init()...wandb: \ Waiting for wandb.init()...wandb: | Waiting for wandb.init()...wandb: | Waiting for wandb.init()...wandb: / Waiting for wandb.init()...wandb: / Waiting for wandb.init()...wandb: - Waiting for wandb.init()...wandb: - Waiting for wandb.init()...wandb: \ Waiting for wandb.init()...wandb: \ Waiting for wandb.init()...wandb: | Waiting for wandb.init()...wandb: | Waiting for wandb.init()...wandb: / Waiting for wandb.init()...wandb: / Waiting for wandb.init()...wandb: - Waiting for wandb.init()...wandb: - Waiting for wandb.init()...wandb: \ Waiting for wandb.init()...wandb: \ Waiting for wandb.init()...wandb: | Waiting for wandb.init()...wandb: | Waiting for wandb.init()...wandb: / Waiting for wandb.init()...wandb: / Waiting for wandb.init()...wandb: - Waiting for wandb.init()...wandb: - Waiting for wandb.init()...wandb: \ Waiting for wandb.init()...wandb: \ Waiting for wandb.init()...wandb: | Waiting for wandb.init()...wandb: | Waiting for wandb.init()...wandb: / Waiting for wandb.init()...wandb: / Waiting for wandb.init()...wandb: - Waiting for wandb.init()...wandb: - Waiting for wandb.init()...wandb: \ Waiting for wandb.init()...wandb: \ Waiting for wandb.init()...wandb: | Waiting for wandb.init()...wandb: | Waiting for wandb.init()...Problem at: /scratch/gpfs/od2961/similarity-paper/similar-behavior/cleanrl/cleanrl/meow_continuous_action.py 244 train
Traceback (most recent call last):
  File "/home/od2961/.conda/envs/similar-behavior/lib/python3.10/site-packages/wandb/sdk/wandb_init.py", line 1144, in init
    run = wi.init()
  File "/home/od2961/.conda/envs/similar-behavior/lib/python3.10/site-packages/wandb/sdk/wandb_init.py", line 773, in init
    raise error
wandb.errors.CommError: Error communicating with wandb process, exiting...
For more info see: https://docs.wandb.ai/guides/track/tracking-faq#initstarterror-error-communicating-with-wandb-process-
WARNING:urllib3.connectionpool:Retrying (Retry(total=2, connect=None, read=None, redirect=None, status=None)) after connection broken by 'NewConnectionError('<urllib3.connection.HTTPSConnection object at 0x14d1d8538f40>: Failed to establish a new connection: [Errno -2] Name or service not known')': /api/5288891/store/
WARNING:urllib3.connectionpool:Retrying (Retry(total=1, connect=None, read=None, redirect=None, status=None)) after connection broken by 'NewConnectionError('<urllib3.connection.HTTPSConnection object at 0x14d1d8538bb0>: Failed to establish a new connection: [Errno -2] Name or service not known')': /api/5288891/store/
WARNING:urllib3.connectionpool:Retrying (Retry(total=0, connect=None, read=None, redirect=None, status=None)) after connection broken by 'NewConnectionError('<urllib3.connection.HTTPSConnection object at 0x14d1d853beb0>: Failed to establish a new connection: [Errno -2] Name or service not known')': /api/5288891/store/
WARNING:urllib3.connectionpool:Retrying (Retry(total=2, connect=None, read=None, redirect=None, status=None)) after connection broken by 'NewConnectionError('<urllib3.connection.HTTPSConnection object at 0x14d1d8539000>: Failed to establish a new connection: [Errno -2] Name or service not known')': /api/5288891/store/
WARNING:urllib3.connectionpool:Retrying (Retry(total=1, connect=None, read=None, redirect=None, status=None)) after connection broken by 'NewConnectionError('<urllib3.connection.HTTPSConnection object at 0x14d1d85389d0>: Failed to establish a new connection: [Errno -2] Name or service not known')': /api/5288891/store/
WARNING:urllib3.connectionpool:Retrying (Retry(total=0, connect=None, read=None, redirect=None, status=None)) after connection broken by 'NewConnectionError('<urllib3.connection.HTTPSConnection object at 0x14d1d8538820>: Failed to establish a new connection: [Errno -2] Name or service not known')': /api/5288891/store/
Problem at: /scratch/gpfs/od2961/similarity-paper/similar-behavior/cleanrl/cleanrl/meow_continuous_action.py 244 train
Traceback (most recent call last):
  File "/home/od2961/.conda/envs/similar-behavior/lib/python3.10/site-packages/wandb/sdk/wandb_init.py", line 1144, in init
    run = wi.init()
  File "/home/od2961/.conda/envs/similar-behavior/lib/python3.10/site-packages/wandb/sdk/wandb_init.py", line 773, in init
    raise error
wandb.errors.CommError: Error communicating with wandb process, exiting...
For more info see: https://docs.wandb.ai/guides/track/tracking-faq#initstarterror-error-communicating-with-wandb-process-
WARNING:urllib3.connectionpool:Retrying (Retry(total=2, connect=None, read=None, redirect=None, status=None)) after connection broken by 'NewConnectionError('<urllib3.connection.HTTPSConnection object at 0x150d59124f40>: Failed to establish a new connection: [Errno -2] Name or service not known')': /api/5288891/store/
WARNING:urllib3.connectionpool:Retrying (Retry(total=1, connect=None, read=None, redirect=None, status=None)) after connection broken by 'NewConnectionError('<urllib3.connection.HTTPSConnection object at 0x150d59124c70>: Failed to establish a new connection: [Errno -2] Name or service not known')': /api/5288891/store/
WARNING:urllib3.connectionpool:Retrying (Retry(total=0, connect=None, read=None, redirect=None, status=None)) after connection broken by 'NewConnectionError('<urllib3.connection.HTTPSConnection object at 0x150d59127ee0>: Failed to establish a new connection: [Errno -2] Name or service not known')': /api/5288891/store/
WARNING:urllib3.connectionpool:Retrying (Retry(total=2, connect=None, read=None, redirect=None, status=None)) after connection broken by 'NewConnectionError('<urllib3.connection.HTTPSConnection object at 0x150d59125000>: Failed to establish a new connection: [Errno -2] Name or service not known')': /api/5288891/store/
WARNING:urllib3.connectionpool:Retrying (Retry(total=1, connect=None, read=None, redirect=None, status=None)) after connection broken by 'NewConnectionError('<urllib3.connection.HTTPSConnection object at 0x150d59124910>: Failed to establish a new connection: [Errno -2] Name or service not known')': /api/5288891/store/
WARNING:urllib3.connectionpool:Retrying (Retry(total=0, connect=None, read=None, redirect=None, status=None)) after connection broken by 'NewConnectionError('<urllib3.connection.HTTPSConnection object at 0x150d59124820>: Failed to establish a new connection: [Errno -2] Name or service not known')': /api/5288891/store/
WARNING:urllib3.connectionpool:Retrying (Retry(total=2, connect=None, read=None, redirect=None, status=None)) after connection broken by 'NewConnectionError('<urllib3.connection.HTTPSConnection object at 0x14d1d85383d0>: Failed to establish a new connection: [Errno -2] Name or service not known')': /api/5288891/envelope/
WARNING:urllib3.connectionpool:Retrying (Retry(total=1, connect=None, read=None, redirect=None, status=None)) after connection broken by 'NewConnectionError('<urllib3.connection.HTTPSConnection object at 0x14d1d8538130>: Failed to establish a new connection: [Errno -2] Name or service not known')': /api/5288891/envelope/
WARNING:urllib3.connectionpool:Retrying (Retry(total=0, connect=None, read=None, redirect=None, status=None)) after connection broken by 'NewConnectionError('<urllib3.connection.HTTPSConnection object at 0x14d1d8538040>: Failed to establish a new connection: [Errno -2] Name or service not known')': /api/5288891/envelope/
WARNING:urllib3.connectionpool:Retrying (Retry(total=2, connect=None, read=None, redirect=None, status=None)) after connection broken by 'NewConnectionError('<urllib3.connection.HTTPSConnection object at 0x150d59124310>: Failed to establish a new connection: [Errno -2] Name or service not known')': /api/5288891/envelope/
WARNING:urllib3.connectionpool:Retrying (Retry(total=1, connect=None, read=None, redirect=None, status=None)) after connection broken by 'NewConnectionError('<urllib3.connection.HTTPSConnection object at 0x150d591241f0>: Failed to establish a new connection: [Errno -2] Name or service not known')': /api/5288891/envelope/
WARNING:urllib3.connectionpool:Retrying (Retry(total=0, connect=None, read=None, redirect=None, status=None)) after connection broken by 'NewConnectionError('<urllib3.connection.HTTPSConnection object at 0x150d59124070>: Failed to establish a new connection: [Errno -2] Name or service not known')': /api/5288891/envelope/
wandb: ERROR Abnormal program exit
Traceback (most recent call last):
  File "/home/od2961/.conda/envs/similar-behavior/lib/python3.10/site-packages/wandb/sdk/wandb_init.py", line 1144, in init
    run = wi.init()
  File "/home/od2961/.conda/envs/similar-behavior/lib/python3.10/site-packages/wandb/sdk/wandb_init.py", line 773, in init
    raise error
wandb.errors.CommError: Error communicating with wandb process, exiting...
For more info see: https://docs.wandb.ai/guides/track/tracking-faq#initstarterror-error-communicating-with-wandb-process-

The above exception was the direct cause of the following exception:

Traceback (most recent call last):
  File "/scratch/gpfs/od2961/similarity-paper/similar-behavior/cleanrl/cleanrl/meow_continuous_action.py", line 432, in <module>
    train()
  File "/scratch/gpfs/od2961/similarity-paper/similar-behavior/cleanrl/cleanrl/meow_continuous_action.py", line 244, in train
    wandb.init(
  File "/home/od2961/.conda/envs/similar-behavior/lib/python3.10/site-packages/wandb/sdk/wandb_init.py", line 1181, in init
    raise Exception("problem") from error_seen
Exception: problem
wandb: ERROR Abnormal program exit
Traceback (most recent call last):
  File "/home/od2961/.conda/envs/similar-behavior/lib/python3.10/site-packages/wandb/sdk/wandb_init.py", line 1144, in init
    run = wi.init()
  File "/home/od2961/.conda/envs/similar-behavior/lib/python3.10/site-packages/wandb/sdk/wandb_init.py", line 773, in init
    raise error
wandb.errors.CommError: Error communicating with wandb process, exiting...
For more info see: https://docs.wandb.ai/guides/track/tracking-faq#initstarterror-error-communicating-with-wandb-process-

The above exception was the direct cause of the following exception:

Traceback (most recent call last):
  File "/scratch/gpfs/od2961/similarity-paper/similar-behavior/cleanrl/cleanrl/meow_continuous_action.py", line 432, in <module>
    train()
  File "/scratch/gpfs/od2961/similarity-paper/similar-behavior/cleanrl/cleanrl/meow_continuous_action.py", line 244, in train
    wandb.init(
  File "/home/od2961/.conda/envs/similar-behavior/lib/python3.10/site-packages/wandb/sdk/wandb_init.py", line 1181, in init
    raise Exception("problem") from error_seen
Exception: problem
Launching experiment meow_walker2d-v4-seed-2-alpha-0.5
Launching experiment meow_walker2d-v4-seed-2-alpha-0.6
/home/od2961/.conda/envs/similar-behavior/lib/python3.10/site-packages/pkg_resources/__init__.py:121: DeprecationWarning: pkg_resources is deprecated as an API
  warnings.warn("pkg_resources is deprecated as an API", DeprecationWarning)
/home/od2961/.conda/envs/similar-behavior/lib/python3.10/site-packages/pkg_resources/__init__.py:121: DeprecationWarning: pkg_resources is deprecated as an API
  warnings.warn("pkg_resources is deprecated as an API", DeprecationWarning)
/home/od2961/.conda/envs/similar-behavior/lib/python3.10/site-packages/pkg_resources/__init__.py:2870: DeprecationWarning: Deprecated call to `pkg_resources.declare_namespace('google')`.
Implementing implicit namespace packages (as specified in PEP 420) is preferred to `pkg_resources.declare_namespace`. See https://setuptools.pypa.io/en/latest/references/keywords.html#keyword-namespace-packages
  declare_namespace(pkg)
/home/od2961/.conda/envs/similar-behavior/lib/python3.10/site-packages/pkg_resources/__init__.py:2870: DeprecationWarning: Deprecated call to `pkg_resources.declare_namespace('mpl_toolkits')`.
Implementing implicit namespace packages (as specified in PEP 420) is preferred to `pkg_resources.declare_namespace`. See https://setuptools.pypa.io/en/latest/references/keywords.html#keyword-namespace-packages
  declare_namespace(pkg)
/home/od2961/.conda/envs/similar-behavior/lib/python3.10/site-packages/pkg_resources/__init__.py:2870: DeprecationWarning: Deprecated call to `pkg_resources.declare_namespace('google')`.
Implementing implicit namespace packages (as specified in PEP 420) is preferred to `pkg_resources.declare_namespace`. See https://setuptools.pypa.io/en/latest/references/keywords.html#keyword-namespace-packages
  declare_namespace(pkg)
/home/od2961/.conda/envs/similar-behavior/lib/python3.10/site-packages/pkg_resources/__init__.py:2870: DeprecationWarning: Deprecated call to `pkg_resources.declare_namespace('google')`.
Implementing implicit namespace packages (as specified in PEP 420) is preferred to `pkg_resources.declare_namespace`. See https://setuptools.pypa.io/en/latest/references/keywords.html#keyword-namespace-packages
  declare_namespace(pkg)
/home/od2961/.conda/envs/similar-behavior/lib/python3.10/site-packages/pkg_resources/__init__.py:2870: DeprecationWarning: Deprecated call to `pkg_resources.declare_namespace('mpl_toolkits')`.
Implementing implicit namespace packages (as specified in PEP 420) is preferred to `pkg_resources.declare_namespace`. See https://setuptools.pypa.io/en/latest/references/keywords.html#keyword-namespace-packages
  declare_namespace(pkg)
/home/od2961/.conda/envs/similar-behavior/lib/python3.10/site-packages/pkg_resources/__init__.py:2870: DeprecationWarning: Deprecated call to `pkg_resources.declare_namespace('google')`.
Implementing implicit namespace packages (as specified in PEP 420) is preferred to `pkg_resources.declare_namespace`. See https://setuptools.pypa.io/en/latest/references/keywords.html#keyword-namespace-packages
  declare_namespace(pkg)
wandb: Network error (ConnectionError), entering retry loop.
wandb: Network error (ConnectionError), entering retry loop.
wandb: W&B API key is configured. Use `wandb login --relogin` to force relogin
wandb: W&B API key is configured. Use `wandb login --relogin` to force relogin
wandb: - Waiting for wandb.init()...wandb: - Waiting for wandb.init()...wandb: \ Waiting for wandb.init()...wandb: \ Waiting for wandb.init()...wandb: | Waiting for wandb.init()...wandb: | Waiting for wandb.init()...wandb: Network error (ConnectionError), entering retry loop.
wandb: Network error (ConnectionError), entering retry loop.
wandb: / Waiting for wandb.init()...wandb: / Waiting for wandb.init()...wandb: - Waiting for wandb.init()...wandb: - Waiting for wandb.init()...wandb: \ Waiting for wandb.init()...wandb: \ Waiting for wandb.init()...wandb: | Waiting for wandb.init()...wandb: | Waiting for wandb.init()...wandb: / Waiting for wandb.init()...wandb: / Waiting for wandb.init()...wandb: - Waiting for wandb.init()...wandb: - Waiting for wandb.init()...wandb: \ Waiting for wandb.init()...wandb: \ Waiting for wandb.init()...wandb: | Waiting for wandb.init()...wandb: | Waiting for wandb.init()...wandb: / Waiting for wandb.init()...wandb: / Waiting for wandb.init()...wandb: - Waiting for wandb.init()...wandb: - Waiting for wandb.init()...wandb: \ Waiting for wandb.init()...wandb: \ Waiting for wandb.init()...wandb: | Waiting for wandb.init()...wandb: | Waiting for wandb.init()...wandb: / Waiting for wandb.init()...wandb: / Waiting for wandb.init()...wandb: - Waiting for wandb.init()...wandb: - Waiting for wandb.init()...wandb: \ Waiting for wandb.init()...wandb: \ Waiting for wandb.init()...wandb: | Waiting for wandb.init()...wandb: | Waiting for wandb.init()...wandb: / Waiting for wandb.init()...wandb: / Waiting for wandb.init()...wandb: - Waiting for wandb.init()...wandb: - Waiting for wandb.init()...wandb: \ Waiting for wandb.init()...wandb: \ Waiting for wandb.init()...wandb: | Waiting for wandb.init()...wandb: | Waiting for wandb.init()...wandb: / Waiting for wandb.init()...wandb: / Waiting for wandb.init()...wandb: - Waiting for wandb.init()...wandb: - Waiting for wandb.init()...wandb: \ Waiting for wandb.init()...wandb: \ Waiting for wandb.init()...wandb: | Waiting for wandb.init()...wandb: | Waiting for wandb.init()...wandb: / Waiting for wandb.init()...wandb: / Waiting for wandb.init()...wandb: - Waiting for wandb.init()...wandb: - Waiting for wandb.init()...wandb: \ Waiting for wandb.init()...wandb: \ Waiting for wandb.init()...wandb: | Waiting for wandb.init()...wandb: | Waiting for wandb.init()...wandb: / Waiting for wandb.init()...wandb: / Waiting for wandb.init()...wandb: - Waiting for wandb.init()...wandb: - Waiting for wandb.init()...wandb: \ Waiting for wandb.init()...wandb: \ Waiting for wandb.init()...wandb: | Waiting for wandb.init()...wandb: | Waiting for wandb.init()...wandb: / Waiting for wandb.init()...wandb: / Waiting for wandb.init()...wandb: - Waiting for wandb.init()...wandb: - Waiting for wandb.init()...wandb: \ Waiting for wandb.init()...wandb: \ Waiting for wandb.init()...wandb: | Waiting for wandb.init()...wandb: | Waiting for wandb.init()...wandb: / Waiting for wandb.init()...wandb: / Waiting for wandb.init()...wandb: - Waiting for wandb.init()...wandb: - Waiting for wandb.init()...wandb: \ Waiting for wandb.init()...wandb: \ Waiting for wandb.init()...wandb: | Waiting for wandb.init()...wandb: | Waiting for wandb.init()...wandb: / Waiting for wandb.init()...wandb: / Waiting for wandb.init()...wandb: - Waiting for wandb.init()...wandb: - Waiting for wandb.init()...wandb: \ Waiting for wandb.init()...wandb: \ Waiting for wandb.init()...wandb: | Waiting for wandb.init()...wandb: | Waiting for wandb.init()...wandb: / Waiting for wandb.init()...wandb: / Waiting for wandb.init()...wandb: - Waiting for wandb.init()...wandb: - Waiting for wandb.init()...wandb: \ Waiting for wandb.init()...wandb: \ Waiting for wandb.init()...wandb: | Waiting for wandb.init()...wandb: | Waiting for wandb.init()...wandb: / Waiting for wandb.init()...wandb: / Waiting for wandb.init()...wandb: - Waiting for wandb.init()...wandb: - Waiting for wandb.init()...wandb: \ Waiting for wandb.init()...wandb: \ Waiting for wandb.init()...wandb: | Waiting for wandb.init()...wandb: | Waiting for wandb.init()...wandb: / Waiting for wandb.init()...wandb: / Waiting for wandb.init()...wandb: - Waiting for wandb.init()...wandb: - Waiting for wandb.init()...wandb: \ Waiting for wandb.init()...wandb: \ Waiting for wandb.init()...wandb: | Waiting for wandb.init()...wandb: | Waiting for wandb.init()...Problem at: /scratch/gpfs/od2961/similarity-paper/similar-behavior/cleanrl/cleanrl/meow_continuous_action.py 244 train
Traceback (most recent call last):
  File "/home/od2961/.conda/envs/similar-behavior/lib/python3.10/site-packages/wandb/sdk/wandb_init.py", line 1144, in init
    run = wi.init()
  File "/home/od2961/.conda/envs/similar-behavior/lib/python3.10/site-packages/wandb/sdk/wandb_init.py", line 773, in init
    raise error
wandb.errors.CommError: Error communicating with wandb process, exiting...
For more info see: https://docs.wandb.ai/guides/track/tracking-faq#initstarterror-error-communicating-with-wandb-process-
WARNING:urllib3.connectionpool:Retrying (Retry(total=2, connect=None, read=None, redirect=None, status=None)) after connection broken by 'NewConnectionError('<urllib3.connection.HTTPSConnection object at 0x14d11f304f40>: Failed to establish a new connection: [Errno -2] Name or service not known')': /api/5288891/store/
WARNING:urllib3.connectionpool:Retrying (Retry(total=1, connect=None, read=None, redirect=None, status=None)) after connection broken by 'NewConnectionError('<urllib3.connection.HTTPSConnection object at 0x14d11f304c70>: Failed to establish a new connection: [Errno -2] Name or service not known')': /api/5288891/store/
WARNING:urllib3.connectionpool:Retrying (Retry(total=0, connect=None, read=None, redirect=None, status=None)) after connection broken by 'NewConnectionError('<urllib3.connection.HTTPSConnection object at 0x14d11f307f40>: Failed to establish a new connection: [Errno -2] Name or service not known')': /api/5288891/store/
WARNING:urllib3.connectionpool:Retrying (Retry(total=2, connect=None, read=None, redirect=None, status=None)) after connection broken by 'NewConnectionError('<urllib3.connection.HTTPSConnection object at 0x14d11f305000>: Failed to establish a new connection: [Errno -2] Name or service not known')': /api/5288891/store/
WARNING:urllib3.connectionpool:Retrying (Retry(total=1, connect=None, read=None, redirect=None, status=None)) after connection broken by 'NewConnectionError('<urllib3.connection.HTTPSConnection object at 0x14d11f304910>: Failed to establish a new connection: [Errno -2] Name or service not known')': /api/5288891/store/
WARNING:urllib3.connectionpool:Retrying (Retry(total=0, connect=None, read=None, redirect=None, status=None)) after connection broken by 'NewConnectionError('<urllib3.connection.HTTPSConnection object at 0x14d11f304820>: Failed to establish a new connection: [Errno -2] Name or service not known')': /api/5288891/store/
Problem at: /scratch/gpfs/od2961/similarity-paper/similar-behavior/cleanrl/cleanrl/meow_continuous_action.py 244 train
Traceback (most recent call last):
  File "/home/od2961/.conda/envs/similar-behavior/lib/python3.10/site-packages/wandb/sdk/wandb_init.py", line 1144, in init
    run = wi.init()
  File "/home/od2961/.conda/envs/similar-behavior/lib/python3.10/site-packages/wandb/sdk/wandb_init.py", line 773, in init
    raise error
wandb.errors.CommError: Error communicating with wandb process, exiting...
For more info see: https://docs.wandb.ai/guides/track/tracking-faq#initstarterror-error-communicating-with-wandb-process-
WARNING:urllib3.connectionpool:Retrying (Retry(total=2, connect=None, read=None, redirect=None, status=None)) after connection broken by 'NewConnectionError('<urllib3.connection.HTTPSConnection object at 0x14bddddd4f10>: Failed to establish a new connection: [Errno -2] Name or service not known')': /api/5288891/store/
WARNING:urllib3.connectionpool:Retrying (Retry(total=1, connect=None, read=None, redirect=None, status=None)) after connection broken by 'NewConnectionError('<urllib3.connection.HTTPSConnection object at 0x14bddddd4b80>: Failed to establish a new connection: [Errno -2] Name or service not known')': /api/5288891/store/
WARNING:urllib3.connectionpool:Retrying (Retry(total=0, connect=None, read=None, redirect=None, status=None)) after connection broken by 'NewConnectionError('<urllib3.connection.HTTPSConnection object at 0x14bddddd5000>: Failed to establish a new connection: [Errno -2] Name or service not known')': /api/5288891/store/
WARNING:urllib3.connectionpool:Retrying (Retry(total=2, connect=None, read=None, redirect=None, status=None)) after connection broken by 'NewConnectionError('<urllib3.connection.HTTPSConnection object at 0x14bddddd7e50>: Failed to establish a new connection: [Errno -2] Name or service not known')': /api/5288891/store/
WARNING:urllib3.connectionpool:Retrying (Retry(total=1, connect=None, read=None, redirect=None, status=None)) after connection broken by 'NewConnectionError('<urllib3.connection.HTTPSConnection object at 0x14bddddd49a0>: Failed to establish a new connection: [Errno -2] Name or service not known')': /api/5288891/store/
WARNING:urllib3.connectionpool:Retrying (Retry(total=0, connect=None, read=None, redirect=None, status=None)) after connection broken by 'NewConnectionError('<urllib3.connection.HTTPSConnection object at 0x14bddddd47f0>: Failed to establish a new connection: [Errno -2] Name or service not known')': /api/5288891/store/
WARNING:urllib3.connectionpool:Retrying (Retry(total=2, connect=None, read=None, redirect=None, status=None)) after connection broken by 'NewConnectionError('<urllib3.connection.HTTPSConnection object at 0x14d11f304310>: Failed to establish a new connection: [Errno -2] Name or service not known')': /api/5288891/envelope/
WARNING:urllib3.connectionpool:Retrying (Retry(total=1, connect=None, read=None, redirect=None, status=None)) after connection broken by 'NewConnectionError('<urllib3.connection.HTTPSConnection object at 0x14d11f3041f0>: Failed to establish a new connection: [Errno -2] Name or service not known')': /api/5288891/envelope/
WARNING:urllib3.connectionpool:Retrying (Retry(total=0, connect=None, read=None, redirect=None, status=None)) after connection broken by 'NewConnectionError('<urllib3.connection.HTTPSConnection object at 0x14d11f304070>: Failed to establish a new connection: [Errno -2] Name or service not known')': /api/5288891/envelope/
WARNING:urllib3.connectionpool:Retrying (Retry(total=2, connect=None, read=None, redirect=None, status=None)) after connection broken by 'NewConnectionError('<urllib3.connection.HTTPSConnection object at 0x14bddddd43a0>: Failed to establish a new connection: [Errno -2] Name or service not known')': /api/5288891/envelope/
WARNING:urllib3.connectionpool:Retrying (Retry(total=1, connect=None, read=None, redirect=None, status=None)) after connection broken by 'NewConnectionError('<urllib3.connection.HTTPSConnection object at 0x14bddddd4100>: Failed to establish a new connection: [Errno -2] Name or service not known')': /api/5288891/envelope/
WARNING:urllib3.connectionpool:Retrying (Retry(total=0, connect=None, read=None, redirect=None, status=None)) after connection broken by 'NewConnectionError('<urllib3.connection.HTTPSConnection object at 0x14bdddda6710>: Failed to establish a new connection: [Errno -2] Name or service not known')': /api/5288891/envelope/
wandb: ERROR Abnormal program exit
Traceback (most recent call last):
  File "/home/od2961/.conda/envs/similar-behavior/lib/python3.10/site-packages/wandb/sdk/wandb_init.py", line 1144, in init
    run = wi.init()
  File "/home/od2961/.conda/envs/similar-behavior/lib/python3.10/site-packages/wandb/sdk/wandb_init.py", line 773, in init
    raise error
wandb.errors.CommError: Error communicating with wandb process, exiting...
For more info see: https://docs.wandb.ai/guides/track/tracking-faq#initstarterror-error-communicating-with-wandb-process-

The above exception was the direct cause of the following exception:

Traceback (most recent call last):
  File "/scratch/gpfs/od2961/similarity-paper/similar-behavior/cleanrl/cleanrl/meow_continuous_action.py", line 432, in <module>
    train()
  File "/scratch/gpfs/od2961/similarity-paper/similar-behavior/cleanrl/cleanrl/meow_continuous_action.py", line 244, in train
    wandb.init(
  File "/home/od2961/.conda/envs/similar-behavior/lib/python3.10/site-packages/wandb/sdk/wandb_init.py", line 1181, in init
    raise Exception("problem") from error_seen
Exception: problem
wandb: ERROR Abnormal program exit
Traceback (most recent call last):
  File "/home/od2961/.conda/envs/similar-behavior/lib/python3.10/site-packages/wandb/sdk/wandb_init.py", line 1144, in init
    run = wi.init()
  File "/home/od2961/.conda/envs/similar-behavior/lib/python3.10/site-packages/wandb/sdk/wandb_init.py", line 773, in init
    raise error
wandb.errors.CommError: Error communicating with wandb process, exiting...
For more info see: https://docs.wandb.ai/guides/track/tracking-faq#initstarterror-error-communicating-with-wandb-process-

The above exception was the direct cause of the following exception:

Traceback (most recent call last):
  File "/scratch/gpfs/od2961/similarity-paper/similar-behavior/cleanrl/cleanrl/meow_continuous_action.py", line 432, in <module>
    train()
  File "/scratch/gpfs/od2961/similarity-paper/similar-behavior/cleanrl/cleanrl/meow_continuous_action.py", line 244, in train
    wandb.init(
  File "/home/od2961/.conda/envs/similar-behavior/lib/python3.10/site-packages/wandb/sdk/wandb_init.py", line 1181, in init
    raise Exception("problem") from error_seen
Exception: problem
Launching experiment meow_walker2d-v4-seed-2-alpha-0
Launching experiment meow_walker2d-v4-seed-2-alpha-0.1
/home/od2961/.conda/envs/similar-behavior/lib/python3.10/site-packages/pkg_resources/__init__.py:121: DeprecationWarning: pkg_resources is deprecated as an API
  warnings.warn("pkg_resources is deprecated as an API", DeprecationWarning)
/home/od2961/.conda/envs/similar-behavior/lib/python3.10/site-packages/pkg_resources/__init__.py:121: DeprecationWarning: pkg_resources is deprecated as an API
  warnings.warn("pkg_resources is deprecated as an API", DeprecationWarning)
/home/od2961/.conda/envs/similar-behavior/lib/python3.10/site-packages/pkg_resources/__init__.py:2870: DeprecationWarning: Deprecated call to `pkg_resources.declare_namespace('google')`.
Implementing implicit namespace packages (as specified in PEP 420) is preferred to `pkg_resources.declare_namespace`. See https://setuptools.pypa.io/en/latest/references/keywords.html#keyword-namespace-packages
  declare_namespace(pkg)
/home/od2961/.conda/envs/similar-behavior/lib/python3.10/site-packages/pkg_resources/__init__.py:2870: DeprecationWarning: Deprecated call to `pkg_resources.declare_namespace('google')`.
Implementing implicit namespace packages (as specified in PEP 420) is preferred to `pkg_resources.declare_namespace`. See https://setuptools.pypa.io/en/latest/references/keywords.html#keyword-namespace-packages
  declare_namespace(pkg)
/home/od2961/.conda/envs/similar-behavior/lib/python3.10/site-packages/pkg_resources/__init__.py:2870: DeprecationWarning: Deprecated call to `pkg_resources.declare_namespace('mpl_toolkits')`.
Implementing implicit namespace packages (as specified in PEP 420) is preferred to `pkg_resources.declare_namespace`. See https://setuptools.pypa.io/en/latest/references/keywords.html#keyword-namespace-packages
  declare_namespace(pkg)
/home/od2961/.conda/envs/similar-behavior/lib/python3.10/site-packages/pkg_resources/__init__.py:2870: DeprecationWarning: Deprecated call to `pkg_resources.declare_namespace('google')`.
Implementing implicit namespace packages (as specified in PEP 420) is preferred to `pkg_resources.declare_namespace`. See https://setuptools.pypa.io/en/latest/references/keywords.html#keyword-namespace-packages
  declare_namespace(pkg)
/home/od2961/.conda/envs/similar-behavior/lib/python3.10/site-packages/pkg_resources/__init__.py:2870: DeprecationWarning: Deprecated call to `pkg_resources.declare_namespace('mpl_toolkits')`.
Implementing implicit namespace packages (as specified in PEP 420) is preferred to `pkg_resources.declare_namespace`. See https://setuptools.pypa.io/en/latest/references/keywords.html#keyword-namespace-packages
  declare_namespace(pkg)
/home/od2961/.conda/envs/similar-behavior/lib/python3.10/site-packages/pkg_resources/__init__.py:2870: DeprecationWarning: Deprecated call to `pkg_resources.declare_namespace('google')`.
Implementing implicit namespace packages (as specified in PEP 420) is preferred to `pkg_resources.declare_namespace`. See https://setuptools.pypa.io/en/latest/references/keywords.html#keyword-namespace-packages
  declare_namespace(pkg)
wandb: Network error (ConnectionError), entering retry loop.
wandb: Network error (ConnectionError), entering retry loop.
wandb: W&B API key is configured. Use `wandb login --relogin` to force relogin
wandb: W&B API key is configured. Use `wandb login --relogin` to force relogin
wandb: - Waiting for wandb.init()...wandb: - Waiting for wandb.init()...wandb: \ Waiting for wandb.init()...wandb: \ Waiting for wandb.init()...wandb: | Waiting for wandb.init()...wandb: | Waiting for wandb.init()...wandb: Network error (ConnectionError), entering retry loop.
wandb: Network error (ConnectionError), entering retry loop.
wandb: / Waiting for wandb.init()...wandb: / Waiting for wandb.init()...wandb: - Waiting for wandb.init()...wandb: - Waiting for wandb.init()...wandb: \ Waiting for wandb.init()...wandb: \ Waiting for wandb.init()...wandb: | Waiting for wandb.init()...wandb: | Waiting for wandb.init()...wandb: / Waiting for wandb.init()...wandb: / Waiting for wandb.init()...wandb: - Waiting for wandb.init()...wandb: - Waiting for wandb.init()...wandb: \ Waiting for wandb.init()...wandb: \ Waiting for wandb.init()...wandb: | Waiting for wandb.init()...wandb: | Waiting for wandb.init()...wandb: / Waiting for wandb.init()...wandb: / Waiting for wandb.init()...wandb: - Waiting for wandb.init()...wandb: - Waiting for wandb.init()...wandb: \ Waiting for wandb.init()...wandb: \ Waiting for wandb.init()...wandb: | Waiting for wandb.init()...wandb: | Waiting for wandb.init()...wandb: / Waiting for wandb.init()...wandb: / Waiting for wandb.init()...wandb: - Waiting for wandb.init()...wandb: - Waiting for wandb.init()...wandb: \ Waiting for wandb.init()...wandb: \ Waiting for wandb.init()...wandb: | Waiting for wandb.init()...wandb: | Waiting for wandb.init()...wandb: / Waiting for wandb.init()...wandb: / Waiting for wandb.init()...wandb: - Waiting for wandb.init()...wandb: - Waiting for wandb.init()...wandb: \ Waiting for wandb.init()...wandb: \ Waiting for wandb.init()...wandb: | Waiting for wandb.init()...wandb: | Waiting for wandb.init()...wandb: / Waiting for wandb.init()...wandb: / Waiting for wandb.init()...wandb: - Waiting for wandb.init()...wandb: - Waiting for wandb.init()...wandb: \ Waiting for wandb.init()...wandb: \ Waiting for wandb.init()...wandb: | Waiting for wandb.init()...wandb: | Waiting for wandb.init()...wandb: / Waiting for wandb.init()...wandb: / Waiting for wandb.init()...wandb: - Waiting for wandb.init()...wandb: - Waiting for wandb.init()...wandb: \ Waiting for wandb.init()...wandb: \ Waiting for wandb.init()...wandb: | Waiting for wandb.init()...wandb: | Waiting for wandb.init()...wandb: / Waiting for wandb.init()...wandb: / Waiting for wandb.init()...wandb: - Waiting for wandb.init()...wandb: - Waiting for wandb.init()...wandb: \ Waiting for wandb.init()...wandb: \ Waiting for wandb.init()...wandb: | Waiting for wandb.init()...wandb: | Waiting for wandb.init()...wandb: / Waiting for wandb.init()...wandb: / Waiting for wandb.init()...wandb: - Waiting for wandb.init()...wandb: - Waiting for wandb.init()...wandb: \ Waiting for wandb.init()...wandb: \ Waiting for wandb.init()...wandb: | Waiting for wandb.init()...wandb: | Waiting for wandb.init()...wandb: / Waiting for wandb.init()...wandb: / Waiting for wandb.init()...wandb: - Waiting for wandb.init()...wandb: - Waiting for wandb.init()...wandb: \ Waiting for wandb.init()...wandb: \ Waiting for wandb.init()...wandb: | Waiting for wandb.init()...wandb: | Waiting for wandb.init()...wandb: / Waiting for wandb.init()...wandb: / Waiting for wandb.init()...wandb: - Waiting for wandb.init()...wandb: - Waiting for wandb.init()...wandb: \ Waiting for wandb.init()...wandb: \ Waiting for wandb.init()...wandb: | Waiting for wandb.init()...wandb: | Waiting for wandb.init()...wandb: / Waiting for wandb.init()...wandb: / Waiting for wandb.init()...wandb: - Waiting for wandb.init()...wandb: - Waiting for wandb.init()...wandb: \ Waiting for wandb.init()...wandb: \ Waiting for wandb.init()...wandb: | Waiting for wandb.init()...wandb: | Waiting for wandb.init()...wandb: / Waiting for wandb.init()...wandb: / Waiting for wandb.init()...wandb: - Waiting for wandb.init()...wandb: - Waiting for wandb.init()...wandb: \ Waiting for wandb.init()...wandb: \ Waiting for wandb.init()...wandb: | Waiting for wandb.init()...wandb: | Waiting for wandb.init()...wandb: / Waiting for wandb.init()...wandb: / Waiting for wandb.init()...wandb: - Waiting for wandb.init()...wandb: - Waiting for wandb.init()...wandb: \ Waiting for wandb.init()...wandb: \ Waiting for wandb.init()...wandb: | Waiting for wandb.init()...wandb: | Waiting for wandb.init()...WARNING:urllib3.connectionpool:Retrying (Retry(total=2, connect=None, read=None, redirect=None, status=None)) after connection broken by 'NewConnectionError('<urllib3.connection.HTTPSConnection object at 0x14aaa9d0bf10>: Failed to establish a new connection: [Errno -2] Name or service not known')': /api/5288891/envelope/
WARNING:urllib3.connectionpool:Retrying (Retry(total=1, connect=None, read=None, redirect=None, status=None)) after connection broken by 'NewConnectionError('<urllib3.connection.HTTPSConnection object at 0x14aaa9d08eb0>: Failed to establish a new connection: [Errno -2] Name or service not known')': /api/5288891/envelope/
WARNING:urllib3.connectionpool:Retrying (Retry(total=0, connect=None, read=None, redirect=None, status=None)) after connection broken by 'NewConnectionError('<urllib3.connection.HTTPSConnection object at 0x14aaa9d08dc0>: Failed to establish a new connection: [Errno -2] Name or service not known')': /api/5288891/envelope/
Problem at: /scratch/gpfs/od2961/similarity-paper/similar-behavior/cleanrl/cleanrl/meow_continuous_action.py 244 train
Traceback (most recent call last):
  File "/home/od2961/.conda/envs/similar-behavior/lib/python3.10/site-packages/wandb/sdk/wandb_init.py", line 1144, in init
    run = wi.init()
  File "/home/od2961/.conda/envs/similar-behavior/lib/python3.10/site-packages/wandb/sdk/wandb_init.py", line 773, in init
    raise error
wandb.errors.CommError: Error communicating with wandb process, exiting...
For more info see: https://docs.wandb.ai/guides/track/tracking-faq#initstarterror-error-communicating-with-wandb-process-
WARNING:urllib3.connectionpool:Retrying (Retry(total=2, connect=None, read=None, redirect=None, status=None)) after connection broken by 'NewConnectionError('<urllib3.connection.HTTPSConnection object at 0x14aaa9d0bfd0>: Failed to establish a new connection: [Errno -2] Name or service not known')': /api/5288891/store/
WARNING:urllib3.connectionpool:Retrying (Retry(total=1, connect=None, read=None, redirect=None, status=None)) after connection broken by 'NewConnectionError('<urllib3.connection.HTTPSConnection object at 0x14aaa9d08df0>: Failed to establish a new connection: [Errno -2] Name or service not known')': /api/5288891/store/
WARNING:urllib3.connectionpool:Retrying (Retry(total=0, connect=None, read=None, redirect=None, status=None)) after connection broken by 'NewConnectionError('<urllib3.connection.HTTPSConnection object at 0x14aaa9d0bf40>: Failed to establish a new connection: [Errno -2] Name or service not known')': /api/5288891/store/
WARNING:urllib3.connectionpool:Retrying (Retry(total=2, connect=None, read=None, redirect=None, status=None)) after connection broken by 'NewConnectionError('<urllib3.connection.HTTPSConnection object at 0x14aaa9d088b0>: Failed to establish a new connection: [Errno -2] Name or service not known')': /api/5288891/store/
WARNING:urllib3.connectionpool:Retrying (Retry(total=1, connect=None, read=None, redirect=None, status=None)) after connection broken by 'NewConnectionError('<urllib3.connection.HTTPSConnection object at 0x14aaa9d086d0>: Failed to establish a new connection: [Errno -2] Name or service not known')': /api/5288891/store/
WARNING:urllib3.connectionpool:Retrying (Retry(total=0, connect=None, read=None, redirect=None, status=None)) after connection broken by 'NewConnectionError('<urllib3.connection.HTTPSConnection object at 0x14aaa9d08520>: Failed to establish a new connection: [Errno -2] Name or service not known')': /api/5288891/store/
Problem at: /scratch/gpfs/od2961/similarity-paper/similar-behavior/cleanrl/cleanrl/meow_continuous_action.py 244 train
WARNING:urllib3.connectionpool:Retrying (Retry(total=2, connect=None, read=None, redirect=None, status=None)) after connection broken by 'NewConnectionError('<urllib3.connection.HTTPSConnection object at 0x14892b047400>: Failed to establish a new connection: [Errno -2] Name or service not known')': /api/5288891/store/
WARNING:urllib3.connectionpool:Retrying (Retry(total=1, connect=None, read=None, redirect=None, status=None)) after connection broken by 'NewConnectionError('<urllib3.connection.HTTPSConnection object at 0x14892b044ee0>: Failed to establish a new connection: [Errno -2] Name or service not known')': /api/5288891/store/
WARNING:urllib3.connectionpool:Retrying (Retry(total=0, connect=None, read=None, redirect=None, status=None)) after connection broken by 'NewConnectionError('<urllib3.connection.HTTPSConnection object at 0x14892b044cd0>: Failed to establish a new connection: [Errno -2] Name or service not known')': /api/5288891/store/
Traceback (most recent call last):
  File "/home/od2961/.conda/envs/similar-behavior/lib/python3.10/site-packages/wandb/sdk/wandb_init.py", line 1144, in init
    run = wi.init()
  File "/home/od2961/.conda/envs/similar-behavior/lib/python3.10/site-packages/wandb/sdk/wandb_init.py", line 773, in init
    raise error
wandb.errors.CommError: Error communicating with wandb process, exiting...
For more info see: https://docs.wandb.ai/guides/track/tracking-faq#initstarterror-error-communicating-with-wandb-process-
WARNING:urllib3.connectionpool:Retrying (Retry(total=2, connect=None, read=None, redirect=None, status=None)) after connection broken by 'NewConnectionError('<urllib3.connection.HTTPSConnection object at 0x14892b044880>: Failed to establish a new connection: [Errno -2] Name or service not known')': /api/5288891/store/
WARNING:urllib3.connectionpool:Retrying (Retry(total=1, connect=None, read=None, redirect=None, status=None)) after connection broken by 'NewConnectionError('<urllib3.connection.HTTPSConnection object at 0x14892b044790>: Failed to establish a new connection: [Errno -2] Name or service not known')': /api/5288891/store/
WARNING:urllib3.connectionpool:Retrying (Retry(total=0, connect=None, read=None, redirect=None, status=None)) after connection broken by 'NewConnectionError('<urllib3.connection.HTTPSConnection object at 0x14892b0446a0>: Failed to establish a new connection: [Errno -2] Name or service not known')': /api/5288891/store/
WARNING:urllib3.connectionpool:Retrying (Retry(total=2, connect=None, read=None, redirect=None, status=None)) after connection broken by 'NewConnectionError('<urllib3.connection.HTTPSConnection object at 0x14892b044190>: Failed to establish a new connection: [Errno -2] Name or service not known')': /api/5288891/envelope/
WARNING:urllib3.connectionpool:Retrying (Retry(total=1, connect=None, read=None, redirect=None, status=None)) after connection broken by 'NewConnectionError('<urllib3.connection.HTTPSConnection object at 0x14892b4468f0>: Failed to establish a new connection: [Errno -2] Name or service not known')': /api/5288891/envelope/
WARNING:urllib3.connectionpool:Retrying (Retry(total=0, connect=None, read=None, redirect=None, status=None)) after connection broken by 'NewConnectionError('<urllib3.connection.HTTPSConnection object at 0x14892b447eb0>: Failed to establish a new connection: [Errno -2] Name or service not known')': /api/5288891/envelope/
wandb: ERROR Abnormal program exit
Traceback (most recent call last):
  File "/home/od2961/.conda/envs/similar-behavior/lib/python3.10/site-packages/wandb/sdk/wandb_init.py", line 1144, in init
    run = wi.init()
  File "/home/od2961/.conda/envs/similar-behavior/lib/python3.10/site-packages/wandb/sdk/wandb_init.py", line 773, in init
    raise error
wandb.errors.CommError: Error communicating with wandb process, exiting...
For more info see: https://docs.wandb.ai/guides/track/tracking-faq#initstarterror-error-communicating-with-wandb-process-

The above exception was the direct cause of the following exception:

Traceback (most recent call last):
  File "/scratch/gpfs/od2961/similarity-paper/similar-behavior/cleanrl/cleanrl/meow_continuous_action.py", line 432, in <module>
    train()
  File "/scratch/gpfs/od2961/similarity-paper/similar-behavior/cleanrl/cleanrl/meow_continuous_action.py", line 244, in train
    wandb.init(
  File "/home/od2961/.conda/envs/similar-behavior/lib/python3.10/site-packages/wandb/sdk/wandb_init.py", line 1181, in init
    raise Exception("problem") from error_seen
Exception: problem
wandb: ERROR Abnormal program exit
Traceback (most recent call last):
  File "/home/od2961/.conda/envs/similar-behavior/lib/python3.10/site-packages/wandb/sdk/wandb_init.py", line 1144, in init
    run = wi.init()
  File "/home/od2961/.conda/envs/similar-behavior/lib/python3.10/site-packages/wandb/sdk/wandb_init.py", line 773, in init
    raise error
wandb.errors.CommError: Error communicating with wandb process, exiting...
For more info see: https://docs.wandb.ai/guides/track/tracking-faq#initstarterror-error-communicating-with-wandb-process-

The above exception was the direct cause of the following exception:

Traceback (most recent call last):
  File "/scratch/gpfs/od2961/similarity-paper/similar-behavior/cleanrl/cleanrl/meow_continuous_action.py", line 432, in <module>
    train()
  File "/scratch/gpfs/od2961/similarity-paper/similar-behavior/cleanrl/cleanrl/meow_continuous_action.py", line 244, in train
    wandb.init(
  File "/home/od2961/.conda/envs/similar-behavior/lib/python3.10/site-packages/wandb/sdk/wandb_init.py", line 1181, in init
    raise Exception("problem") from error_seen
Exception: problem
